Workbook

Sheet README
A1: TA metric map
A2: What exists today in TA reporting, linked end to end: platform, table, script, metric, product. Validate the rows; the Decisions sheet reads them back as the choices to make.
A4: The chain | B4: Platforms (where data is born) -> Tables (warehouse, custom, shared, hand-kept) -> Scripts (what reads and writes them, when, started by whom) -> Metrics (one row per definition, with the fields they read) -> Products (what people look at, and what each reads directly).
A6: How to read a link | B6: Every link shows a name, never a code. The grey columns next to a name hold the ID the tools use; leave them alone. Short name is the key: give every table, script and product two or three words that stay stable.
A7: How to add a link | B7: Type the name in the cream column (there is a drop-down). The grey column resolves it, or says Not found.
A8: Multi-value links | B8: Built from, Reads, Writes, Feeds, Reads from: comma-separated names. Run the skill's sync (or ask it to) after editing; it fills the grey ID columns and the derived name columns, and raises a Question for any name it cannot match.
A10: Who fills what | B10: The skill fills everything it can from files and proposes the judgement columns, labelled Review = Proposed. A person accepts, corrects or rejects. Disposition and the Decision log are only ever a person's. Platform on each source table is a person's, from PDP's mapping.
A11: Three columns only a person who runs the product can answer | B11: Products: Last hop into the product, Automation level, Manual effort.
A13: Colour code
A14: Dark blue header | B14: Column names. Hover for the meaning and an example; the Column guide sheet has the same text.
A15: Light blue | B15: Short names: the human keys. Unique on each sheet.
A16: Cream | B16: Text, names and drop-downs for the skill or a person to fill.
A17: Green text | B17: Formulas. Do not type over them.
A18: Grey | B18: IDs and helpers the tools maintain. Leave them alone.
A19: Amber Proposed | B19: A Review value of Proposed means a tool wrote the row and nobody has checked it.
A21: Order of work | B21: 1 Products and what each reads. 2 Tables and the scripts that build them. 3 Metrics and the fields they read. 4 Dimensions. 5 Validate the Proposed rows. 6 Read Decisions. 7 Record what is agreed in the Decision log.
A22: No examples | B22: This workbook ships empty on purpose. Everything in it comes from your files or your people.

Sheet Decisions
A1: Decisions
A2: Read-only. Each number is a choice to make; click through to the rows behind it. Numbers come from the sheets and update as rows are validated.
A4: Standardise metrics
A5: =COUNTA(Metrics!$A$5:$A$304) -> 0 | B5: =HYPERLINK("#Metrics!A4","Metrics in the inventory") -> Metrics in the inventory | C5: Every distinct definition found, before any merging.
A6: =SUMPRODUCT((Metrics!$A$5:$A$304<>"")*(Metrics!$O$5:$O$304=0)) -> 0 | B6: =HYPERLINK("#Metrics!A4","Metrics with a definition nobody else has") -> Metrics with a definition nobody else has | C6: The truly distinct ones.
A7: =SUMPRODUCT((Metrics!$A$5:$A$304<>"")*(Metrics!$O$5:$O$304>0)) -> 0 | B7: =HYPERLINK("#Metrics!A4","Metrics that share a definition with another row") -> Metrics that share a definition with another row | C7: Same thing under two names: merge candidates.
A8: =SUMPRODUCT((Families!$A$5:$A$44<>"")*(Families!$E$5:$E$44>1)) -> 0 | B8: =HYPERLINK("#Families!A4","Families with more than one definition") -> Families with more than one definition | C8: Same question, different rules: the alignment agenda with TAAA.
A9: =SUMPRODUCT((Metrics!$A$5:$A$304<>"")*(Metrics!$K$5:$K$304>1)) -> 0 | B9: =HYPERLINK("#Metrics!A4","Metrics pulled from more than one table") -> Metrics pulled from more than one table | C9: Where numbers can disagree even when the definition matches. Check each one's Reads from tables.
A10: =SUMPRODUCT((Metrics!$A$5:$A$304<>"")*(Metrics!$D$5:$D$304="")) -> 0 | B10: =HYPERLINK("#Metrics!A4","Metrics with no definition") -> Metrics with no definition | C10: A number on a product with no formula anywhere we can see.
A12: Standardise tables
A13: =COUNTA(Tables!$A$5:$A$304) -> 0 | B13: =HYPERLINK("#Tables!A4","Tables in the inventory") -> Tables in the inventory | C13: Warehouse, custom, shared and hand-kept, together.
A14: =SUMPRODUCT((Tables!$A$5:$A$304<>"")*(ISNUMBER(Tables!$O$5:$O$304))*(Tables!$O$5:$O$304>=2))+COUNTIF(Tables!$O$5:$O$304,"4+") -> 0 | B14: =HYPERLINK("#Tables!A4","Stacked tables (depth 2 or more)") -> Stacked tables (depth 2 or more) | C14: Layers built on layers: the simplification candidates.
A15: =COUNTIF(Tables!$D$5:$D$304,"Manual spreadsheet") -> 0 | B15: =HYPERLINK("#Tables!A4","Hand-maintained spreadsheets in the chain") -> Hand-maintained spreadsheets in the chain | C15: One person away from breaking.
A16: =SUMPRODUCT((Tables!$D$5:$D$304="Team custom")*(Tables!$H$5:$H$304="")) -> 0 | B16: =HYPERLINK("#Tables!A4","Custom tables with no known builder") -> Custom tables with no known builder | C16: Nothing in the files writes them; who refreshes them?
A17: =SUMPRODUCT((Tables!$D$5:$D$304="Team custom")*(Tables!$S$5:$S$304=0)) -> 0 | B17: =HYPERLINK("#Tables!A4","Custom tables no metric depends on") -> Custom tables no metric depends on | C17: Retire signal, once the fields are traced.
A18: =SUMPRODUCT((Tables!$A$5:$A$304<>"")*((Tables!$D$5:$D$304="HRDW")+(Tables!$D$5:$D$304="Platform extract"))*(Tables!$E$5:$E$304="")) -> 0 | B18: =HYPERLINK("#Tables!A4","Source tables with no platform recorded") -> Source tables with no platform recorded | C18: Fill from PDP's mapping.
A20: Simplify products
A21: =COUNTA(Products!$A$5:$A$154) -> 0 | B21: =HYPERLINK("#Products!A4","Products in the inventory") -> Products in the inventory
A22: =COUNTIF(Products!$P$5:$P$154,"Automated") -> 0 | B22: =HYPERLINK("#Products!A4","Automated end to end") -> Automated end to end
A23: =COUNTIF(Products!$P$5:$P$154,"Partly manual")+COUNTIF(Products!$P$5:$P$154,"Manual") -> 0 | B23: =HYPERLINK("#Products!A4","Partly manual or manual") -> Partly manual or manual | C23: The automation backlog; Manual steps says what.
A24: =COUNTIF(Products!$O$5:$O$154,"Pasted by hand") -> 0 | B24: =HYPERLINK("#Products!A4","Products where numbers are pasted in by hand") -> Products where numbers are pasted in by hand | C24: The last hop.
A25: =SUMPRODUCT((Products!$A$5:$A$154<>"")*(Products!$T$5:$T$154>0)) -> 0 | B25: =HYPERLINK("#Products!A4","Products reading a hand-maintained spreadsheet") -> Products reading a hand-maintained spreadsheet
A26: =COUNTIF(Scripts!$M$5:$M$304,"Manual run") -> 0 | B26: =HYPERLINK("#Scripts!A4","Scripts someone has to start by hand") -> Scripts someone has to start by hand
A27: =COUNTIF(Scripts!$O$5:$O$304,"Nobody is told") -> 0 | B27: =HYPERLINK("#Scripts!A4","Scripts nobody is told about when they fail") -> Scripts nobody is told about when they fail
A28: =COUNTIF('Dimension usage'!$G$5:$G$404,"No") -> 0 | B28: =HYPERLINK("#'Dimension usage'!A4","Dimension cuts taken from the wrong table") -> Dimension cuts taken from the wrong table | C28: Same filter name, different mapping.
A30: Still to validate
A31: =COUNTIF(Products!$W$5:$W$154,"Proposed")+COUNTIF(Metrics!$T$5:$T$304,"Proposed")+COUNTIF(Tables!$Y$5:$Y$304,"Proposed")+COUNTIF(Scripts!$R$5:$R$304,"Proposed")+COUNTIF(Fields!$S$5:$S$704,"Proposed") -> 0 | B31: =HYPERLINK("#Products!A4","Rows a tool wrote that nobody has checked") -> Rows a tool wrote that nobody has checked | C31: Work these down, highest impact first.
A32: =COUNTIF(Questions!$H$5:$H$504,"Open") -> 0 | B32: =HYPERLINK("#Questions!A4","Open questions") -> Open questions
A33: =COUNTIF(Incidents!$G$5:$G$504,"Unknown") -> 0 | B33: =HYPERLINK("#Incidents!A4","Incidents with no root stage") -> Incidents with no root stage

Sheet Column guide
A1: Column guide
A2: Every column on every sheet, who fills it, what it means, and an example. The same text sits on each column header as a hover note.
A4: Sheet | B4: Column | C4: Who fills it | D4: What it means | E4: Example
A5: Platforms | B5: Platform name | C5: A person | D5: The system's name as people say it. | E5: Workday Recruiting
A6: Platforms | B6: What it holds | C6: A person | D6: One sentence on what is entered or recorded there. | E6: Requisitions, candidates, offers and hires as recruiters enter them.
A7: Platforms | B7: Point of contact | C7: A person | D7: Who to ask about the feed from this platform. | E7: PDP integrations team
A8: Platforms | B8: Tables fed | C8: Filled automatically | D8: How many tables on the Tables sheet name this platform as their origin. | E8: 3
A9: Platforms | B9: Notes | C9: A person | D9: Anything else.
A10: Families | B10: Family (the question it answers) | C10: A person | D10: The question in plain words. This exact text goes in the Metric family column. | E10: How long does hiring take?
A11: Families | B11: Old name | C11: A person | D11: The category name people used before. | E11: Cycle time
A12: Families | B12: What it covers | C12: A person | D12: One sentence on what belongs here. | E12: Elapsed days between two events in the hiring process.
A13: Families | B13: Example metrics | C13: A person | D13: Names people will recognise. | E13: Approved to accepted; Posted to start
A14: Families | B14: Metrics in family | C14: Filled automatically | D14: How many Metrics rows use this family. | E14: 3
A15: Products | B15: Product ID | C15: The tools | D15: Assigned by the tools. Never typed. | E15: P-001
A16: Products | B16: Short name | C16: The skill, from files | D16: Two or three words, unique. This is how the product is named everywhere else in the workbook. | E16: TA scorecard
A17: Products | B17: Full name | C17: The skill, from files | D17: The file or workbook name as it is. | E17: TA_Scorecard_FY26.xlsx
A18: Products | B18: Type | C18: The skill, from files | D18: Scorecard = the executive view. Dashboard = a Tableau or QuickSight view. Sent report = emailed or posted on a schedule. Data pull = a recurring extract. | E18: Scorecard
A19: Products | B19: Tool | C19: The skill, from files | D19: Where it lives. | E19: Excel
A20: Products | B20: Audience | C20: The skill proposes; a person confirms | D20: Who looks at it. | E20: TA leadership
A21: Products | B21: Owner (team) | C21: The skill proposes; a person confirms | D21: Team responsible for keeping it working. | E21: Team Opportunity
... A73: Metric to Product | B73: How it is shown | C73: The skill, from files | D73: What the product does with it: headline tile, trend, table, one tab per org. | E73: Headline number, one tab per org, by month.
A74: Metric to Product | B74: Notes | C74: The skill, from files | D74: Anything else.
A75: Metric to Product | B75: Review | C75: A person | D75: Proposed = a tool wrote the row and nobody has checked it. Accepted = a person agreed. Corrected = a person changed it. Rejected = wrong; the correction is in the cell or in a Question. | E75: Accepted
A76: Metric to Product | B76: Source (where found) | C76: The skill, from files | D76: The file, sheet, cell, notebook cell or conversation the row came from. Specific enough to open it. | E76: scorecard.xlsx, tab Eng, cell B5
A77: Metric to Product | B77: Confidence | C77: The skill, from files | D77: Found = read directly from a file. Inferred = deduced from more than one file or a naming pattern; Notes says how. Proposed = a best reading where no file states it. Human = a person entered or confirmed it. | E77: Found
A78: Tables | B78: Table ID | C78: The tools | D78: Assigned by the tools. | E78: T-004
A79: Tables | B79: Short name | C79: The skill, from files | D79: Two or three words, unique. Used everywhere a human reads a link. | E79: req linkage
A80: Tables | B80: Full name | C80: The skill, from files | D80: schema.table as written in the source, or the file name for a spreadsheet. | E80: ta_custom.req_linkage
A81: Tables | B81: Kind | C81: The skill, from files | D81: HRDW = a warehouse table as delivered by PDP. Team custom = a table our team builds. Shared (other team) = another team's table we read. Manual spreadsheet = a file a person maintains by hand. Script output file = a file a script writes (an xlsx or csv). Platform extract = a direct feed from a recruiting system. | E81: Team custom
A82: Tables | B82: Platform | C82: A person | D82: The system this data is born in. Only on HRDW and Platform extract tables. A person fills it from PDP's mapping; the tools never guess it. | E82: Workday Recruiting
A83: Tables | B83: Built from | C83: The skill, from files | D83: The tables it is built from, by short name, main parent first. The lineage chain follows the first one. | E83: req history, HRDW requisitions
A84: Tables | B84: Built by | C84: The tools | D84: The script that writes it, by short name. Maintained by the tools from the Scripts sheet. | E84: req linkage notebook
A85: Tables | B85: Refresh mechanism | C85: The tools | D85: Scheduled job, Manual run (someone starts the script), Manual spreadsheet (someone edits the file), Live query, Unknown. Set by the tools from the building script's trigger. | E85: Manual run
A86: Tables | B86: Refresh frequency | C86: The skill, from files | D86: How often it updates, from the script's schedule or from a person. | E86: Daily
... A98: Tables | B98: Phase | C98: A person | D98: Phase 1 = sits under a scorecard metric. | E98: Phase 1
A99: Tables | B99: Notes | C99: The skill, from files | D99: File that creates it, anything odd.
A100: Tables | B100: Review | C100: A person | D100: Proposed = a tool wrote the row and nobody has checked it. Accepted = a person agreed. Corrected = a person changed it. Rejected = wrong; the correction is in the cell or in a Question. | E100: Accepted
A101: Tables | B101: Source (where found) | C101: The skill, from files | D101: The file, sheet, cell, notebook cell or conversation the row came from. Specific enough to open it. | E101: scorecard.xlsx, tab Eng, cell B5
A102: Tables | B102: Confidence | C102: The skill, from files | D102: Found = read directly from a file. Inferred = deduced from more than one file or a naming pattern; Notes says how. Proposed = a best reading where no file states it. Human = a person entered or confirmed it. | E102: Found
A103: Tables | B103: Last verified | C103: A person | D103: Date a person last confirmed the row is still true. | E103: 2026-10-13
...

Sheet Products
A1: Products
A2: One row per thing people look at: the scorecard, dashboards, sent reports, data pulls. What it reads comes from the Product inputs sheet.
A4: Product ID | B4: Short name | C4: Full name | D4: Type | E4: Tool | F4: Audience | G4: Owner (team) | H4: Point of contact | I4: Refresh frequency | J4: Delivery cadence | K4: Reads from | L4: h_reads_ids | M4: Fed by scripts | N4: h_fed_ids | O4: Last hop into the product | P4: Automation level | Q4: Manual steps | R4: Manual effort (hours per cycle) | S4: Metrics shown | T4: Manual spreadsheets read | U4: Phase | V4: Notes | W4: Review | X4: Source (where found) | Y4: Confidence | Z4: Last verified | AA4: Verified by
S5: =IF(A5="","",COUNTIF('Metric to Product'!$B:$B,A5)) | T5: =IF(A5="","",COUNTIFS('Product inputs'!$B:$B,A5,'Product inputs'!$E:$E,"Manual spreadsheet"))
S6: =IF(A6="","",COUNTIF('Metric to Product'!$B:$B,A6)) | T6: =IF(A6="","",COUNTIFS('Product inputs'!$B:$B,A6,'Product inputs'!$E:$E,"Manual spreadsheet"))
S7: =IF(A7="","",COUNTIF('Metric to Product'!$B:$B,A7)) | T7: =IF(A7="","",COUNTIFS('Product inputs'!$B:$B,A7,'Product inputs'!$E:$E,"Manual spreadsheet"))
S8: =IF(A8="","",COUNTIF('Metric to Product'!$B:$B,A8)) | T8: =IF(A8="","",COUNTIFS('Product inputs'!$B:$B,A8,'Product inputs'!$E:$E,"Manual spreadsheet"))
S9: =IF(A9="","",COUNTIF('Metric to Product'!$B:$B,A9)) | T9: =IF(A9="","",COUNTIFS('Product inputs'!$B:$B,A9,'Product inputs'!$E:$E,"Manual spreadsheet"))
S10: =IF(A10="","",COUNTIF('Metric to Product'!$B:$B,A10)) | T10: =IF(A10="","",COUNTIFS('Product inputs'!$B:$B,A10,'Product inputs'!$E:$E,"Manual spreadsheet"))
S11: =IF(A11="","",COUNTIF('Metric to Product'!$B:$B,A11)) | T11: =IF(A11="","",COUNTIFS('Product inputs'!$B:$B,A11,'Product inputs'!$E:$E,"Manual spreadsheet"))
S12: =IF(A12="","",COUNTIF('Metric to Product'!$B:$B,A12)) | T12: =IF(A12="","",COUNTIFS('Product inputs'!$B:$B,A12,'Product inputs'!$E:$E,"Manual spreadsheet"))
S13: =IF(A13="","",COUNTIF('Metric to Product'!$B:$B,A13)) | T13: =IF(A13="","",COUNTIFS('Product inputs'!$B:$B,A13,'Product inputs'!$E:$E,"Manual spreadsheet"))
S14: =IF(A14="","",COUNTIF('Metric to Product'!$B:$B,A14)) | T14: =IF(A14="","",COUNTIFS('Product inputs'!$B:$B,A14,'Product inputs'!$E:$E,"Manual spreadsheet"))
S15: =IF(A15="","",COUNTIF('Metric to Product'!$B:$B,A15)) | T15: =IF(A15="","",COUNTIFS('Product inputs'!$B:$B,A15,'Product inputs'!$E:$E,"Manual spreadsheet"))
S16: =IF(A16="","",COUNTIF('Metric to Product'!$B:$B,A16)) | T16: =IF(A16="","",COUNTIFS('Product inputs'!$B:$B,A16,'Product inputs'!$E:$E,"Manual spreadsheet"))
... S154: =IF(A154="","",COUNTIF('Metric to Product'!$B:$B,A154)) | T154: =IF(A154="","",COUNTIFS('Product inputs'!$B:$B,A154,'Product inputs'!$E:$E,"Manual spreadsheet"))

Sheet Product inputs
A1: Product inputs
A2: One row per table or spreadsheet a product reads directly. Type names; the grey columns resolve them. This is where 'reads from tables, or tables and sheets' is answered.
A4: Product | B4: h_product_id | C4: Table | D4: h_table_id | E4: Table kind | F4: How it gets in | G4: Origin of this row | H4: Notes | I4: Review | J4: Source (where found) | K4: Confidence
B5: =IF(A5="","",IFERROR(INDEX(Products!$A:$A,MATCH(A5,Products!$B:$B,0)),"Not found")) | D5: =IF(C5="","",IFERROR(INDEX(Tables!$A:$A,MATCH(C5,Tables!$B:$B,0)),"Not found")) | E5: =IF(D5="","",IFERROR(INDEX(Tables!$D:$D,MATCH(D5,Tables!$A:$A,0)),""))
B6: =IF(A6="","",IFERROR(INDEX(Products!$A:$A,MATCH(A6,Products!$B:$B,0)),"Not found")) | D6: =IF(C6="","",IFERROR(INDEX(Tables!$A:$A,MATCH(C6,Tables!$B:$B,0)),"Not found")) | E6: =IF(D6="","",IFERROR(INDEX(Tables!$D:$D,MATCH(D6,Tables!$A:$A,0)),""))
B7: =IF(A7="","",IFERROR(INDEX(Products!$A:$A,MATCH(A7,Products!$B:$B,0)),"Not found")) | D7: =IF(C7="","",IFERROR(INDEX(Tables!$A:$A,MATCH(C7,Tables!$B:$B,0)),"Not found")) | E7: =IF(D7="","",IFERROR(INDEX(Tables!$D:$D,MATCH(D7,Tables!$A:$A,0)),""))
B8: =IF(A8="","",IFERROR(INDEX(Products!$A:$A,MATCH(A8,Products!$B:$B,0)),"Not found")) | D8: =IF(C8="","",IFERROR(INDEX(Tables!$A:$A,MATCH(C8,Tables!$B:$B,0)),"Not found")) | E8: =IF(D8="","",IFERROR(INDEX(Tables!$D:$D,MATCH(D8,Tables!$A:$A,0)),""))
B9: =IF(A9="","",IFERROR(INDEX(Products!$A:$A,MATCH(A9,Products!$B:$B,0)),"Not found")) | D9: =IF(C9="","",IFERROR(INDEX(Tables!$A:$A,MATCH(C9,Tables!$B:$B,0)),"Not found")) | E9: =IF(D9="","",IFERROR(INDEX(Tables!$D:$D,MATCH(D9,Tables!$A:$A,0)),""))
B10: =IF(A10="","",IFERROR(INDEX(Products!$A:$A,MATCH(A10,Products!$B:$B,0)),"Not found")) | D10: =IF(C10="","",IFERROR(INDEX(Tables!$A:$A,MATCH(C10,Tables!$B:$B,0)),"Not found")) | E10: =IF(D10="","",IFERROR(INDEX(Tables!$D:$D,MATCH(D10,Tables!$A:$A,0)),""))
B11: =IF(A11="","",IFERROR(INDEX(Products!$A:$A,MATCH(A11,Products!$B:$B,0)),"Not found")) | D11: =IF(C11="","",IFERROR(INDEX(Tables!$A:$A,MATCH(C11,Tables!$B:$B,0)),"Not found")) | E11: =IF(D11="","",IFERROR(INDEX(Tables!$D:$D,MATCH(D11,Tables!$A:$A,0)),""))
B12: =IF(A12="","",IFERROR(INDEX(Products!$A:$A,MATCH(A12,Products!$B:$B,0)),"Not found")) | D12: =IF(C12="","",IFERROR(INDEX(Tables!$A:$A,MATCH(C12,Tables!$B:$B,0)),"Not found")) | E12: =IF(D12="","",IFERROR(INDEX(Tables!$D:$D,MATCH(D12,Tables!$A:$A,0)),""))
B13: =IF(A13="","",IFERROR(INDEX(Products!$A:$A,MATCH(A13,Products!$B:$B,0)),"Not found")) | D13: =IF(C13="","",IFERROR(INDEX(Tables!$A:$A,MATCH(C13,Tables!$B:$B,0)),"Not found")) | E13: =IF(D13="","",IFERROR(INDEX(Tables!$D:$D,MATCH(D13,Tables!$A:$A,0)),""))
B14: =IF(A14="","",IFERROR(INDEX(Products!$A:$A,MATCH(A14,Products!$B:$B,0)),"Not found")) | D14: =IF(C14="","",IFERROR(INDEX(Tables!$A:$A,MATCH(C14,Tables!$B:$B,0)),"Not found")) | E14: =IF(D14="","",IFERROR(INDEX(Tables!$D:$D,MATCH(D14,Tables!$A:$A,0)),""))
B15: =IF(A15="","",IFERROR(INDEX(Products!$A:$A,MATCH(A15,Products!$B:$B,0)),"Not found")) | D15: =IF(C15="","",IFERROR(INDEX(Tables!$A:$A,MATCH(C15,Tables!$B:$B,0)),"Not found")) | E15: =IF(D15="","",IFERROR(INDEX(Tables!$D:$D,MATCH(D15,Tables!$A:$A,0)),""))
B16: =IF(A16="","",IFERROR(INDEX(Products!$A:$A,MATCH(A16,Products!$B:$B,0)),"Not found")) | D16: =IF(C16="","",IFERROR(INDEX(Tables!$A:$A,MATCH(C16,Tables!$B:$B,0)),"Not found")) | E16: =IF(D16="","",IFERROR(INDEX(Tables!$D:$D,MATCH(D16,Tables!$A:$A,0)),""))
... B504: =IF(A504="","",IFERROR(INDEX(Products!$A:$A,MATCH(A504,Products!$B:$B,0)),"Not found")) | D504: =IF(C504="","",IFERROR(INDEX(Tables!$A:$A,MATCH(C504,Tables!$B:$B,0)),"Not found")) | E504: =IF(D504="","",IFERROR(INDEX(Tables!$D:$D,MATCH(D504,Tables!$A:$A,0)),""))

Sheet Metrics
A1: Metrics
A2: One row per distinct definition. Same rule on a different cut or tab = one row. Same name with a different rule = two rows in one family.
A4: Metric ID | B4: Metric family | C4: Metric name | D4: Definition (plain words) | E4: Who is counted | F4: Who is left out | G4: Grain (one row per) | H4: Unit | I4: Reads from tables | J4: h_tables_ids | K4: Tables read | L4: Products using it | M4: Fields needed | N4: Definitions in family | O4: Same definition elsewhere | P4: Owner | Q4: Phase | R4: Notes | S4: h_defkey | T4: Review | U4: Source (where found) | V4: Confidence | W4: Last verified | X4: Verified by
K5: =IF(A5="","",IF(I5="",0,LEN(I5)-LEN(SUBSTITUTE(I5,",",""))+1)) | L5: =IF(A5="","",COUNTIF('Metric to Product'!$A:$A,A5)) | M5: =IF(A5="","",COUNTIF('Metric to Field'!$A:$A,A5)) | N5: =IF(B5="","",COUNTIF($B:$B,B5)) | O5: =IF(A5="","",COUNTIF($S:$S,S5)-1) | S5: =IF(A5="","",LOWER(TRIM(D5&"|"&E5&"|"&F5)))
K6: =IF(A6="","",IF(I6="",0,LEN(I6)-LEN(SUBSTITUTE(I6,",",""))+1)) | L6: =IF(A6="","",COUNTIF('Metric to Product'!$A:$A,A6)) | M6: =IF(A6="","",COUNTIF('Metric to Field'!$A:$A,A6)) | N6: =IF(B6="","",COUNTIF($B:$B,B6)) | O6: =IF(A6="","",COUNTIF($S:$S,S6)-1) | S6: =IF(A6="","",LOWER(TRIM(D6&"|"&E6&"|"&F6)))
K7: =IF(A7="","",IF(I7="",0,LEN(I7)-LEN(SUBSTITUTE(I7,",",""))+1)) | L7: =IF(A7="","",COUNTIF('Metric to Product'!$A:$A,A7)) | M7: =IF(A7="","",COUNTIF('Metric to Field'!$A:$A,A7)) | N7: =IF(B7="","",COUNTIF($B:$B,B7)) | O7: =IF(A7="","",COUNTIF($S:$S,S7)-1) | S7: =IF(A7="","",LOWER(TRIM(D7&"|"&E7&"|"&F7)))
K8: =IF(A8="","",IF(I8="",0,LEN(I8)-LEN(SUBSTITUTE(I8,",",""))+1)) | L8: =IF(A8="","",COUNTIF('Metric to Product'!$A:$A,A8)) | M8: =IF(A8="","",COUNTIF('Metric to Field'!$A:$A,A8)) | N8: =IF(B8="","",COUNTIF($B:$B,B8)) | O8: =IF(A8="","",COUNTIF($S:$S,S8)-1) | S8: =IF(A8="","",LOWER(TRIM(D8&"|"&E8&"|"&F8)))
K9: =IF(A9="","",IF(I9="",0,LEN(I9)-LEN(SUBSTITUTE(I9,",",""))+1)) | L9: =IF(A9="","",COUNTIF('Metric to Product'!$A:$A,A9)) | M9: =IF(A9="","",COUNTIF('Metric to Field'!$A:$A,A9)) | N9: =IF(B9="","",COUNTIF($B:$B,B9)) | O9: =IF(A9="","",COUNTIF($S:$S,S9)-1) | S9: =IF(A9="","",LOWER(TRIM(D9&"|"&E9&"|"&F9)))
K10: =IF(A10="","",IF(I10="",0,LEN(I10)-LEN(SUBSTITUTE(I10,",",""))+1)) | L10: =IF(A10="","",COUNTIF('Metric to Product'!$A:$A,A10)) | M10: =IF(A10="","",COUNTIF('Metric to Field'!$A:$A,A10)) | N10: =IF(B10="","",COUNTIF($B:$B,B10)) | O10: =IF(A10="","",COUNTIF($S:$S,S10)-1) | S10: =IF(A10="","",LOWER(TRIM(D10&"|"&E10&"|"&F10)))
K11: =IF(A11="","",IF(I11="",0,LEN(I11)-LEN(SUBSTITUTE(I11,",",""))+1)) | L11: =IF(A11="","",COUNTIF('Metric to Product'!$A:$A,A11)) | M11: =IF(A11="","",COUNTIF('Metric to Field'!$A:$A,A11)) | N11: =IF(B11="","",COUNTIF($B:$B,B11)) | O11: =IF(A11="","",COUNTIF($S:$S,S11)-1) | S11: =IF(A11="","",LOWER(TRIM(D11&"|"&E11&"|"&F11)))
K12: =IF(A12="","",IF(I12="",0,LEN(I12)-LEN(SUBSTITUTE(I12,",",""))+1)) | L12: =IF(A12="","",COUNTIF('Metric to Product'!$A:$A,A12)) | M12: =IF(A12="","",COUNTIF('Metric to Field'!$A:$A,A12)) | N12: =IF(B12="","",COUNTIF($B:$B,B12)) | O12: =IF(A12="","",COUNTIF($S:$S,S12)-1) | S12: =IF(A12="","",LOWER(TRIM(D12&"|"&E12&"|"&F12)))
K13: =IF(A13="","",IF(I13="",0,LEN(I13)-LEN(SUBSTITUTE(I13,",",""))+1)) | L13: =IF(A13="","",COUNTIF('Metric to Product'!$A:$A,A13)) | M13: =IF(A13="","",COUNTIF('Metric to Field'!$A:$A,A13)) | N13: =IF(B13="","",COUNTIF($B:$B,B13)) | O13: =IF(A13="","",COUNTIF($S:$S,S13)-1) | S13: =IF(A13="","",LOWER(TRIM(D13&"|"&E13&"|"&F13)))
K14: =IF(A14="","",IF(I14="",0,LEN(I14)-LEN(SUBSTITUTE(I14,",",""))+1)) | L14: =IF(A14="","",COUNTIF('Metric to Product'!$A:$A,A14)) | M14: =IF(A14="","",COUNTIF('Metric to Field'!$A:$A,A14)) | N14: =IF(B14="","",COUNTIF($B:$B,B14)) | O14: =IF(A14="","",COUNTIF($S:$S,S14)-1) | S14: =IF(A14="","",LOWER(TRIM(D14&"|"&E14&"|"&F14)))
K15: =IF(A15="","",IF(I15="",0,LEN(I15)-LEN(SUBSTITUTE(I15,",",""))+1)) | L15: =IF(A15="","",COUNTIF('Metric to Product'!$A:$A,A15)) | M15: =IF(A15="","",COUNTIF('Metric to Field'!$A:$A,A15)) | N15: =IF(B15="","",COUNTIF($B:$B,B15)) | O15: =IF(A15="","",COUNTIF($S:$S,S15)-1) | S15: =IF(A15="","",LOWER(TRIM(D15&"|"&E15&"|"&F15)))
K16: =IF(A16="","",IF(I16="",0,LEN(I16)-LEN(SUBSTITUTE(I16,",",""))+1)) | L16: =IF(A16="","",COUNTIF('Metric to Product'!$A:$A,A16)) | M16: =IF(A16="","",COUNTIF('Metric to Field'!$A:$A,A16)) | N16: =IF(B16="","",COUNTIF($B:$B,B16)) | O16: =IF(A16="","",COUNTIF($S:$S,S16)-1) | S16: =IF(A16="","",LOWER(TRIM(D16&"|"&E16&"|"&F16)))
... K304: =IF(A304="","",IF(I304="",0,LEN(I304)-LEN(SUBSTITUTE(I304,",",""))+1)) | L304: =IF(A304="","",COUNTIF('Metric to Product'!$A:$A,A304)) | M304: =IF(A304="","",COUNTIF('Metric to Field'!$A:$A,A304)) | N304: =IF(B304="","",COUNTIF($B:$B,B304)) | O304: =IF(A304="","",COUNTIF($S:$S,S304)-1) | S304: =IF(A304="","",LOWER(TRIM(D304&"|"&E304&"|"&F304)))

Sheet Metric to Product
A1: Metric to Product
A2: One row per place a metric appears. Type the two names; the grey columns resolve them.
A4: h_metric_id | B4: h_product_id | C4: Metric | D4: Product | E4: How it is shown | F4: Notes | G4: Review | H4: Source (where found) | I4: Confidence
A5: =IF(C5="","",IFERROR(INDEX(Metrics!$A:$A,MATCH(C5,Metrics!$C:$C,0)),"Not found")) | B5: =IF(D5="","",IFERROR(INDEX(Products!$A:$A,MATCH(D5,Products!$B:$B,0)),"Not found"))
A6: =IF(C6="","",IFERROR(INDEX(Metrics!$A:$A,MATCH(C6,Metrics!$C:$C,0)),"Not found")) | B6: =IF(D6="","",IFERROR(INDEX(Products!$A:$A,MATCH(D6,Products!$B:$B,0)),"Not found"))
A7: =IF(C7="","",IFERROR(INDEX(Metrics!$A:$A,MATCH(C7,Metrics!$C:$C,0)),"Not found")) | B7: =IF(D7="","",IFERROR(INDEX(Products!$A:$A,MATCH(D7,Products!$B:$B,0)),"Not found"))
A8: =IF(C8="","",IFERROR(INDEX(Metrics!$A:$A,MATCH(C8,Metrics!$C:$C,0)),"Not found")) | B8: =IF(D8="","",IFERROR(INDEX(Products!$A:$A,MATCH(D8,Products!$B:$B,0)),"Not found"))
A9: =IF(C9="","",IFERROR(INDEX(Metrics!$A:$A,MATCH(C9,Metrics!$C:$C,0)),"Not found")) | B9: =IF(D9="","",IFERROR(INDEX(Products!$A:$A,MATCH(D9,Products!$B:$B,0)),"Not found"))
A10: =IF(C10="","",IFERROR(INDEX(Metrics!$A:$A,MATCH(C10,Metrics!$C:$C,0)),"Not found")) | B10: =IF(D10="","",IFERROR(INDEX(Products!$A:$A,MATCH(D10,Products!$B:$B,0)),"Not found"))
A11: =IF(C11="","",IFERROR(INDEX(Metrics!$A:$A,MATCH(C11,Metrics!$C:$C,0)),"Not found")) | B11: =IF(D11="","",IFERROR(INDEX(Products!$A:$A,MATCH(D11,Products!$B:$B,0)),"Not found"))
A12: =IF(C12="","",IFERROR(INDEX(Metrics!$A:$A,MATCH(C12,Metrics!$C:$C,0)),"Not found")) | B12: =IF(D12="","",IFERROR(INDEX(Products!$A:$A,MATCH(D12,Products!$B:$B,0)),"Not found"))
A13: =IF(C13="","",IFERROR(INDEX(Metrics!$A:$A,MATCH(C13,Metrics!$C:$C,0)),"Not found")) | B13: =IF(D13="","",IFERROR(INDEX(Products!$A:$A,MATCH(D13,Products!$B:$B,0)),"Not found"))
A14: =IF(C14="","",IFERROR(INDEX(Metrics!$A:$A,MATCH(C14,Metrics!$C:$C,0)),"Not found")) | B14: =IF(D14="","",IFERROR(INDEX(Products!$A:$A,MATCH(D14,Products!$B:$B,0)),"Not found"))
A15: =IF(C15="","",IFERROR(INDEX(Metrics!$A:$A,MATCH(C15,Metrics!$C:$C,0)),"Not found")) | B15: =IF(D15="","",IFERROR(INDEX(Products!$A:$A,MATCH(D15,Products!$B:$B,0)),"Not found"))
A16: =IF(C16="","",IFERROR(INDEX(Metrics!$A:$A,MATCH(C16,Metrics!$C:$C,0)),"Not found")) | B16: =IF(D16="","",IFERROR(INDEX(Products!$A:$A,MATCH(D16,Products!$B:$B,0)),"Not found"))
... A604: =IF(C604="","",IFERROR(INDEX(Metrics!$A:$A,MATCH(C604,Metrics!$C:$C,0)),"Not found")) | B604: =IF(D604="","",IFERROR(INDEX(Products!$A:$A,MATCH(D604,Products!$B:$B,0)),"Not found"))

Sheet Tables
A1: Tables
A2: Every table or file a product or script reads or writes: warehouse tables, our own tables, other teams' tables, hand-kept spreadsheets. Lineage comes from Built from; refresh comes from the script that builds it.
A4: Table ID | B4: Short name | C4: Full name | D4: Kind | E4: Platform | F4: Built from | G4: h_built_from_ids | H4: Built by | I4: h_built_by_id | J4: Refresh mechanism | K4: Refresh frequency | L4: Why it exists | M4: Owner (team) | N4: Point of contact | O4: Depth | P4: Lineage chain | Q4: Root platform | R4: Fields listed | S4: Metrics depending | T4: Products reading it directly | U4: Target layer | V4: Disposition | W4: Phase | X4: Notes | Y4: Review | Z4: Source (where found) | AA4: Confidence | AB4: Last verified | AC4: Verified by | AD4: h_p1 | AE4: h_p2 | AF4: h_p3 | AG4: h_p4
O5: =IF(A5="","",IF(AD5="",0,IF(AE5="",1,IF(AF5="",2,IF(AG5="",3,"4+"))))) | P5: =IF(A5="","",B5&IF(AD5="",""," <- "&IFERROR(INDEX($B:$B,MATCH(AD5,$A:$A,0)),AD5)&IF(AE5="",""," <- "&IFERROR(INDEX($B:$B,MATCH(AE5,$A:$A,0)),AE5)&IF(AF5="",""," <- "&IFERROR(INDEX($B:$B,MATCH(AF5,$A:$A,0)),AF5)&IF(AG5="",""," <- "&IFERROR(INDEX($B:$B,MATCH(AG5,$A:$A,0)),AG5)))))&IF(ISNUMBER(FIND(",",G5))," (+ other parents)","")) | Q5: =IF(A5="","",IF(AD5="",E5&"",IF(AE5="",IF(IFERROR(INDEX($E:$E,MATCH(AD5,$A:$A,0)),"")="","",INDEX($E:$E,MATCH(AD5,$A:$A,0))),IF(AF5="",IF(IFERROR(INDEX($E:$E,MATCH(AE5,$A:$A,0)),"")="","",INDEX($E:$E,MATCH(AE5,$A:$A,0))),IF(AG5="",IF(IFERROR(INDEX($E:$E,MATCH(AF5,$A:$A,0)),"")="","",INDEX($E:$E,MATCH(AF5,$A:$A,0))),IF(IFERROR(INDEX($E:$E,MATCH(AG5,$A:$A,0)),"")="","",INDEX($E:$E,MATCH(AG5,$A:$A,0)))))))) | R5: =IF(A5="","",COUNTIF(Fields!$D:$D,A5)) | S5: =IF(A5="","",SUMIF(Fields!$D:$D,A5,Fields!$Q:$Q)) | T5: =IF(A5="","",COUNTIF('Product inputs'!$D:$D,A5)) | AD5: =IF(A5="","",IF(IFERROR(INDEX($G:$G,MATCH(A5,$A:$A,0)),"")="","",TRIM(IF(ISNUMBER(FIND(",",IFERROR(INDEX($G:$G,MATCH(A5,$A:$A,0)),""))),LEFT(IFERROR(INDEX($G:$G,MATCH(A5,$A:$A,0)),""),FIND(",",IFERROR(INDEX($G:$G,MATCH(A5,$A:$A,0)),""))-1),IFERROR(INDEX($G:$G,MATCH(A5,$A:$A,0)),""))))) | AE5: =IF(AD5="","",IF(IFERROR(INDEX($G:$G,MATCH(AD5,$A:$A,0)),"")="","",TRIM(IF(ISNUMBER(FIND(",",IFERROR(INDEX($G:$G,MATCH(AD5,$A:$A,0)),""))),LEFT(IFERROR(INDEX($G:$G,MATCH(AD5,$A:$A,0)),""),FIND(",",IFERROR(INDEX($G:$G,MATCH(AD5,$A:$A,0)),""))-1),IFERROR(INDEX($G:$G,MATCH(AD5,$A:$A,0)),""))))) | AF5: =IF(AE5="","",IF(IFERROR(INDEX($G:$G,MATCH(AE5,$A:$A,0)),"")="","",TRIM(IF(ISNUMBER(FIND(",",IFERROR(INDEX($G:$G,MATCH(AE5,$A:$A,0)),""))),LEFT(IFERROR(INDEX($G:$G,MATCH(AE5,$A:$A,0)),""),FIND(",",IFERROR(INDEX($G:$G,MATCH(AE5,$A:$A,0)),""))-1),IFERROR(INDEX($G:$G,MATCH(AE5,$A:$A,0)),""))))) | AG5: =IF(AF5="","",IF(IFERROR(INDEX($G:$G,MATCH(AF5,$A:$A,0)),"")="","",TRIM(IF(ISNUMBER(FIND(",",IFERROR(INDEX($G:$G,MATCH(AF5,$A:$A,0)),""))),LEFT(IFERROR(INDEX($G:$G,MATCH(AF5,$A:$A,0)),""),FIND(",",IFERROR(INDEX($G:$G,MATCH(AF5,$A:$A,0)),""))-1),IFERROR(INDEX($G:$G,MATCH(AF5,$A:$A,0)),"")))))
O6: =IF(A6="","",IF(AD6="",0,IF(AE6="",1,IF(AF6="",2,IF(AG6="",3,"4+"))))) | P6: =IF(A6="","",B6&IF(AD6="",""," <- "&IFERROR(INDEX($B:$B,MATCH(AD6,$A:$A,0)),AD6)&IF(AE6="",""," <- "&IFERROR(INDEX($B:$B,MATCH(AE6,$A:$A,0)),AE6)&IF(AF6="",""," <- "&IFERROR(INDEX($B:$B,MATCH(AF6,$A:$A,0)),AF6)&IF(AG6="",""," <- "&IFERROR(INDEX($B:$B,MATCH(AG6,$A:$A,0)),AG6)))))&IF(ISNUMBER(FIND(",",G6))," (+ other parents)","")) | Q6: =IF(A6="","",IF(AD6="",E6&"",IF(AE6="",IF(IFERROR(INDEX($E:$E,MATCH(AD6,$A:$A,0)),"")="","",INDEX($E:$E,MATCH(AD6,$A:$A,0))),IF(AF6="",IF(IFERROR(INDEX($E:$E,MATCH(AE6,$A:$A,0)),"")="","",INDEX($E:$E,MATCH(AE6,$A:$A,0))),IF(AG6="",IF(IFERROR(INDEX($E:$E,MATCH(AF6,$A:$A,0)),"")="","",INDEX($E:$E,MATCH(AF6,$A:$A,0))),IF(IFERROR(INDEX($E:$E,MATCH(AG6,$A:$A,0)),"")="","",INDEX($E:$E,MATCH(AG6,$A:$A,0)))))))) | R6: =IF(A6="","",COUNTIF(Fields!$D:$D,A6)) | S6: =IF(A6="","",SUMIF(Fields!$D:$D,A6,Fields!$Q:$Q)) | T6: =IF(A6="","",COUNTIF('Product inputs'!$D:$D,A6)) | AD6: =IF(A6="","",IF(IFERROR(INDEX($G:$G,MATCH(A6,$A:$A,0)),"")="","",TRIM(IF(ISNUMBER(FIND(",",IFERROR(INDEX($G:$G,MATCH(A6,$A:$A,0)),""))),LEFT(IFERROR(INDEX($G:$G,MATCH(A6,$A:$A,0)),""),FIND(",",IFERROR(INDEX($G:$G,MATCH(A6,$A:$A,0)),""))-1),IFERROR(INDEX($G:$G,MATCH(A6,$A:$A,0)),""))))) | AE6: =IF(AD6="","",IF(IFERROR(INDEX($G:$G,MATCH(AD6,$A:$A,0)),"")="","",TRIM(IF(ISNUMBER(FIND(",",IFERROR(INDEX($G:$G,MATCH(AD6,$A:$A,0)),""))),LEFT(IFERROR(INDEX($G:$G,MATCH(AD6,$A:$A,0)),""),FIND(",",IFERROR(INDEX($G:$G,MATCH(AD6,$A:$A,0)),""))-1),IFERROR(INDEX($G:$G,MATCH(AD6,$A:$A,0)),""))))) | AF6: =IF(AE6="","",IF(IFERROR(INDEX($G:$G,MATCH(AE6,$A:$A,0)),"")="","",TRIM(IF(ISNUMBER(FIND(",",IFERROR(INDEX($G:$G,MATCH(AE6,$A:$A,0)),""))),LEFT(IFERROR(INDEX($G:$G,MATCH(AE6,$A:$A,0)),""),FIND(",",IFERROR(INDEX($G:$G,MATCH(AE6,$A:$A,0)),""))-1),IFERROR(INDEX($G:$G,MATCH(AE6,$A:$A,0)),""))))) | AG6: =IF(AF6="","",IF(IFERROR(INDEX($G:$G,MATCH(AF6,$A:$A,0)),"")="","",TRIM(IF(ISNUMBER(FIND(",",IFERROR(INDEX($G:$G,MATCH(AF6,$A:$A,0)),""))),LEFT(IFERROR(INDEX($G:$G,MATCH(AF6,$A:$A,0)),""),FIND(",",IFERROR(INDEX($G:$G,MATCH(AF6,$A:$A,0)),""))-1),IFERROR(INDEX($G:$G,MATCH(AF6,$A:$A,0)),"")))))
O7: =IF(A7="","",IF(AD7="",0,IF(AE7="",1,IF(AF7="",2,IF(AG7="",3,"4+"))))) | P7: =IF(A7="","",B7&IF(AD7="",""," <- "&IFERROR(INDEX($B:$B,MATCH(AD7,$A:$A,0)),AD7)&IF(AE7="",""," <- "&IFERROR(INDEX($B:$B,MATCH(AE7,$A:$A,0)),AE7)&IF(AF7="",""," <- "&IFERROR(INDEX($B:$B,MATCH(AF7,$A:$A,0)),AF7)&IF(AG7="",""," <- "&IFERROR(INDEX($B:$B,MATCH(AG7,$A:$A,0)),AG7)))))&IF(ISNUMBER(FIND(",",G7))," (+ other parents)","")) | Q7: =IF(A7="","",IF(AD7="",E7&"",IF(AE7="",IF(IFERROR(INDEX($E:$E,MATCH(AD7,$A:$A,0)),"")="","",INDEX($E:$E,MATCH(AD7,$A:$A,0))),IF(AF7="",IF(IFERROR(INDEX($E:$E,MATCH(AE7,$A:$A,0)),"")="","",INDEX($E:$E,MATCH(AE7,$A:$A,0))),IF(AG7="",IF(IFERROR(INDEX($E:$E,MATCH(AF7,$A:$A,0)),"")="","",INDEX($E:$E,MATCH(AF7,$A:$A,0))),IF(IFERROR(INDEX($E:$E,MATCH(AG7,$A:$A,0)),"")="","",INDEX($E:$E,MATCH(AG7,$A:$A,0)))))))) | R7: =IF(A7="","",COUNTIF(Fields!$D:$D,A7)) | S7: =IF(A7="","",SUMIF(Fields!$D:$D,A7,Fields!$Q:$Q)) | T7: =IF(A7="","",COUNTIF('Product inputs'!$D:$D,A7)) | AD7: =IF(A7="","",IF(IFERROR(INDEX($G:$G,MATCH(A7,$A:$A,0)),"")="","",TRIM(IF(ISNUMBER(FIND(",",IFERROR(INDEX($G:$G,MATCH(A7,$A:$A,0)),""))),LEFT(IFERROR(INDEX($G:$G,MATCH(A7,$A:$A,0)),""),FIND(",",IFERROR(INDEX($G:$G,MATCH(A7,$A:$A,0)),""))-1),IFERROR(INDEX($G:$G,MATCH(A7,$A:$A,0)),""))))) | AE7: =IF(AD7="","",IF(IFERROR(INDEX($G:$G,MATCH(AD7,$A:$A,0)),"")="","",TRIM(IF(ISNUMBER(FIND(",",IFERROR(INDEX($G:$G,MATCH(AD7,$A:$A,0)),""))),LEFT(IFERROR(INDEX($G:$G,MATCH(AD7,$A:$A,0)),""),FIND(",",IFERROR(INDEX($G:$G,MATCH(AD7,$A:$A,0)),""))-1),IFERROR(INDEX($G:$G,MATCH(AD7,$A:$A,0)),""))))) | AF7: =IF(AE7="","",IF(IFERROR(INDEX($G:$G,MATCH(AE7,$A:$A,0)),"")="","",TRIM(IF(ISNUMBER(FIND(",",IFERROR(INDEX($G:$G,MATCH(AE7,$A:$A,0)),""))),LEFT(IFERROR(INDEX($G:$G,MATCH(AE7,$A:$A,0)),""),FIND(",",IFERROR(INDEX($G:$G,MATCH(AE7,$A:$A,0)),""))-1),IFERROR(INDEX($G:$G,MATCH(AE7,$A:$A,0)),""))))) | AG7: =IF(AF7="","",IF(IFERROR(INDEX($G:$G,MATCH(AF7,$A:$A,0)),"")="","",TRIM(IF(ISNUMBER(FIND(",",IFERROR(INDEX($G:$G,MATCH(AF7,$A:$A,0)),""))),LEFT(IFERROR(INDEX($G:$G,MATCH(AF7,$A:$A,0)),""),FIND(",",IFERROR(INDEX($G:$G,MATCH(AF7,$A:$A,0)),""))-1),IFERROR(INDEX($G:$G,MATCH(AF7,$A:$A,0)),"")))))
O8: =IF(A8="","",IF(AD8="",0,IF(AE8="",1,IF(AF8="",2,IF(AG8="",3,"4+"))))) | P8: =IF(A8="","",B8&IF(AD8="",""," <- "&IFERROR(INDEX($B:$B,MATCH(AD8,$A:$A,0)),AD8)&IF(AE8="",""," <- "&IFERROR(INDEX($B:$B,MATCH(AE8,$A:$A,0)),AE8)&IF(AF8="",""," <- "&IFERROR(INDEX($B:$B,MATCH(AF8,$A:$A,0)),AF8)&IF(AG8="",""," <- "&IFERROR(INDEX($B:$B,MATCH(AG8,$A:$A,0)),AG8)))))&IF(ISNUMBER(FIND(",",G8))," (+ other parents)","")) | Q8: =IF(A8="","",IF(AD8="",E8&"",IF(AE8="",IF(IFERROR(INDEX($E:$E,MATCH(AD8,$A:$A,0)),"")="","",INDEX($E:$E,MATCH(AD8,$A:$A,0))),IF(AF8="",IF(IFERROR(INDEX($E:$E,MATCH(AE8,$A:$A,0)),"")="","",INDEX($E:$E,MATCH(AE8,$A:$A,0))),IF(AG8="",IF(IFERROR(INDEX($E:$E,MATCH(AF8,$A:$A,0)),"")="","",INDEX($E:$E,MATCH(AF8,$A:$A,0))),IF(IFERROR(INDEX($E:$E,MATCH(AG8,$A:$A,0)),"")="","",INDEX($E:$E,MATCH(AG8,$A:$A,0)))))))) | R8: =IF(A8="","",COUNTIF(Fields!$D:$D,A8)) | S8: =IF(A8="","",SUMIF(Fields!$D:$D,A8,Fields!$Q:$Q)) | T8: =IF(A8="","",COUNTIF('Product inputs'!$D:$D,A8)) | AD8: =IF(A8="","",IF(IFERROR(INDEX($G:$G,MATCH(A8,$A:$A,0)),"")="","",TRIM(IF(ISNUMBER(FIND(",",IFERROR(INDEX($G:$G,MATCH(A8,$A:$A,0)),""))),LEFT(IFERROR(INDEX($G:$G,MATCH(A8,$A:$A,0)),""),FIND(",",IFERROR(INDEX($G:$G,MATCH(A8,$A:$A,0)),""))-1),IFERROR(INDEX($G:$G,MATCH(A8,$A:$A,0)),""))))) | AE8: =IF(AD8="","",IF(IFERROR(INDEX($G:$G,MATCH(AD8,$A:$A,0)),"")="","",TRIM(IF(ISNUMBER(FIND(",",IFERROR(INDEX($G:$G,MATCH(AD8,$A:$A,0)),""))),LEFT(IFERROR(INDEX($G:$G,MATCH(AD8,$A:$A,0)),""),FIND(",",IFERROR(INDEX($G:$G,MATCH(AD8,$A:$A,0)),""))-1),IFERROR(INDEX($G:$G,MATCH(AD8,$A:$A,0)),""))))) | AF8: =IF(AE8="","",IF(IFERROR(INDEX($G:$G,MATCH(AE8,$A:$A,0)),"")="","",TRIM(IF(ISNUMBER(FIND(",",IFERROR(INDEX($G:$G,MATCH(AE8,$A:$A,0)),""))),LEFT(IFERROR(INDEX($G:$G,MATCH(AE8,$A:$A,0)),""),FIND(",",IFERROR(INDEX($G:$G,MATCH(AE8,$A:$A,0)),""))-1),IFERROR(INDEX($G:$G,MATCH(AE8,$A:$A,0)),""))))) | AG8: =IF(AF8="","",IF(IFERROR(INDEX($G:$G,MATCH(AF8,$A:$A,0)),"")="","",TRIM(IF(ISNUMBER(FIND(",",IFERROR(INDEX($G:$G,MATCH(AF8,$A:$A,0)),""))),LEFT(IFERROR(INDEX($G:$G,MATCH(AF8,$A:$A,0)),""),FIND(",",IFERROR(INDEX($G:$G,MATCH(AF8,$A:$A,0)),""))-1),IFERROR(INDEX($G:$G,MATCH(AF8,$A:$A,0)),"")))))
O9: =IF(A9="","",IF(AD9="",0,IF(AE9="",1,IF(AF9="",2,IF(AG9="",3,"4+"))))) | P9: =IF(A9="","",B9&IF(AD9="",""," <- "&IFERROR(INDEX($B:$B,MATCH(AD9,$A:$A,0)),AD9)&IF(AE9="",""," <- "&IFERROR(INDEX($B:$B,MATCH(AE9,$A:$A,0)),AE9)&IF(AF9="",""," <- "&IFERROR(INDEX($B:$B,MATCH(AF9,$A:$A,0)),AF9)&IF(AG9="",""," <- "&IFERROR(INDEX($B:$B,MATCH(AG9,$A:$A,0)),AG9)))))&IF(ISNUMBER(FIND(",",G9))," (+ other parents)","")) | Q9: =IF(A9="","",IF(AD9="",E9&"",IF(AE9="",IF(IFERROR(INDEX($E:$E,MATCH(AD9,$A:$A,0)),"")="","",INDEX($E:$E,MATCH(AD9,$A:$A,0))),IF(AF9="",IF(IFERROR(INDEX($E:$E,MATCH(AE9,$A:$A,0)),"")="","",INDEX($E:$E,MATCH(AE9,$A:$A,0))),IF(AG9="",IF(IFERROR(INDEX($E:$E,MATCH(AF9,$A:$A,0)),"")="","",INDEX($E:$E,MATCH(AF9,$A:$A,0))),IF(IFERROR(INDEX($E:$E,MATCH(AG9,$A:$A,0)),"")="","",INDEX($E:$E,MATCH(AG9,$A:$A,0)))))))) | R9: =IF(A9="","",COUNTIF(Fields!$D:$D,A9)) | S9: =IF(A9="","",SUMIF(Fields!$D:$D,A9,Fields!$Q:$Q)) | T9: =IF(A9="","",COUNTIF('Product inputs'!$D:$D,A9)) | AD9: =IF(A9="","",IF(IFERROR(INDEX($G:$G,MATCH(A9,$A:$A,0)),"")="","",TRIM(IF(ISNUMBER(FIND(",",IFERROR(INDEX($G:$G,MATCH(A9,$A:$A,0)),""))),LEFT(IFERROR(INDEX($G:$G,MATCH(A9,$A:$A,0)),""),FIND(",",IFERROR(INDEX($G:$G,MATCH(A9,$A:$A,0)),""))-1),IFERROR(INDEX($G:$G,MATCH(A9,$A:$A,0)),""))))) | AE9: =IF(AD9="","",IF(IFERROR(INDEX($G:$G,MATCH(AD9,$A:$A,0)),"")="","",TRIM(IF(ISNUMBER(FIND(",",IFERROR(INDEX($G:$G,MATCH(AD9,$A:$A,0)),""))),LEFT(IFERROR(INDEX($G:$G,MATCH(AD9,$A:$A,0)),""),FIND(",",IFERROR(INDEX($G:$G,MATCH(AD9,$A:$A,0)),""))-1),IFERROR(INDEX($G:$G,MATCH(AD9,$A:$A,0)),""))))) | AF9: =IF(AE9="","",IF(IFERROR(INDEX($G:$G,MATCH(AE9,$A:$A,0)),"")="","",TRIM(IF(ISNUMBER(FIND(",",IFERROR(INDEX($G:$G,MATCH(AE9,$A:$A,0)),""))),LEFT(IFERROR(INDEX($G:$G,MATCH(AE9,$A:$A,0)),""),FIND(",",IFERROR(INDEX($G:$G,MATCH(AE9,$A:$A,0)),""))-1),IFERROR(INDEX($G:$G,MATCH(AE9,$A:$A,0)),""))))) | AG9: =IF(AF9="","",IF(IFERROR(INDEX($G:$G,MATCH(AF9,$A:$A,0)),"")="","",TRIM(IF(ISNUMBER(FIND(",",IFERROR(INDEX($G:$G,MATCH(AF9,$A:$A,0)),""))),LEFT(IFERROR(INDEX($G:$G,MATCH(AF9,$A:$A,0)),""),FIND(",",IFERROR(INDEX($G:$G,MATCH(AF9,$A:$A,0)),""))-1),IFERROR(INDEX($G:$G,MATCH(AF9,$A:$A,0)),"")))))
O10: =IF(A10="","",IF(AD10="",0,IF(AE10="",1,IF(AF10="",2,IF(AG10="",3,"4+"))))) | P10: =IF(A10="","",B10&IF(AD10="",""," <- "&IFERROR(INDEX($B:$B,MATCH(AD10,$A:$A,0)),AD10)&IF(AE10="",""," <- "&IFERROR(INDEX($B:$B,MATCH(AE10,$A:$A,0)),AE10)&IF(AF10="",""," <- "&IFERROR(INDEX($B:$B,MATCH(AF10,$A:$A,0)),AF10)&IF(AG10="",""," <- "&IFERROR(INDEX($B:$B,MATCH(AG10,$A:$A,0)),AG10)))))&IF(ISNUMBER(FIND(",",G10))," (+ other parents)","")) | Q10: =IF(A10="","",IF(AD10="",E10&"",IF(AE10="",IF(IFERROR(INDEX($E:$E,MATCH(AD10,$A:$A,0)),"")="","",INDEX($E:$E,MATCH(AD10,$A:$A,0))),IF(AF10="",IF(IFERROR(INDEX($E:$E,MATCH(AE10,$A:$A,0)),"")="","",INDEX($E:$E,MATCH(AE10,$A:$A,0))),IF(AG10="",IF(IFERROR(INDEX($E:$E,MATCH(AF10,$A:$A,0)),"")="","",INDEX($E:$E,MATCH(AF10,$A:$A,0))),IF(IFERROR(INDEX($E:$E,MATCH(AG10,$A:$A,0)),"")="","",INDEX($E:$E,MATCH(AG10,$A:$A,0)))))))) | R10: =IF(A10="","",COUNTIF(Fields!$D:$D,A10)) | S10: =IF(A10="","",SUMIF(Fields!$D:$D,A10,Fields!$Q:$Q)) | T10: =IF(A10="","",COUNTIF('Product inputs'!$D:$D,A10)) | AD10: =IF(A10="","",IF(IFERROR(INDEX($G:$G,MATCH(A10,$A:$A,0)),"")="","",TRIM(IF(ISNUMBER(FIND(",",IFERROR(INDEX($G:$G,MATCH(A10,$A:$A,0)),""))),LEFT(IFERROR(INDEX($G:$G,MATCH(A10,$A:$A,0)),""),FIND(",",IFERROR(INDEX($G:$G,MATCH(A10,$A:$A,0)),""))-1),IFERROR(INDEX($G:$G,MATCH(A10,$A:$A,0)),""))))) | AE10: =IF(AD10="","",IF(IFERROR(INDEX($G:$G,MATCH(AD10,$A:$A,0)),"")="","",TRIM(IF(ISNUMBER(FIND(",",IFERROR(INDEX($G:$G,MATCH(AD10,$A:$A,0)),""))),LEFT(IFERROR(INDEX($G:$G,MATCH(AD10,$A:$A,0)),""),FIND(",",IFERROR(INDEX($G:$G,MATCH(AD10,$A:$A,0)),""))-1),IFERROR(INDEX($G:$G,MATCH(AD10,$A:$A,0)),""))))) | AF10: =IF(AE10="","",IF(IFERROR(INDEX($G:$G,MATCH(AE10,$A:$A,0)),"")="","",TRIM(IF(ISNUMBER(FIND(",",IFERROR(INDEX($G:$G,MATCH(AE10,$A:$A,0)),""))),LEFT(IFERROR(INDEX($G:$G,MATCH(AE10,$A:$A,0)),""),FIND(",",IFERROR(INDEX($G:$G,MATCH(AE10,$A:$A,0)),""))-1),IFERROR(INDEX($G:$G,MATCH(AE10,$A:$A,0)),""))))) | AG10: =IF(AF10="","",IF(IFERROR(INDEX($G:$G,MATCH(AF10,$A:$A,0)),"")="","",TRIM(IF(ISNUMBER(FIND(",",IFERROR(INDEX($G:$G,MATCH(AF10,$A:$A,0)),""))),LEFT(IFERROR(INDEX($G:$G,MATCH(AF10,$A:$A,0)),""),FIND(",",IFERROR(INDEX($G:$G,MATCH(AF10,$A:$A,0)),""))-1),IFERROR(INDEX($G:$G,MATCH(AF10,$A:$A,0)),"")))))
O11: =IF(A11="","",IF(AD11="",0,IF(AE11="",1,IF(AF11="",2,IF(AG11="",3,"4+"))))) | P11: =IF(A11="","",B11&IF(AD11="",""," <- "&IFERROR(INDEX($B:$B,MATCH(AD11,$A:$A,0)),AD11)&IF(AE11="",""," <- "&IFERROR(INDEX($B:$B,MATCH(AE11,$A:$A,0)),AE11)&IF(AF11="",""," <- "&IFERROR(INDEX($B:$B,MATCH(AF11,$A:$A,0)),AF11)&IF(AG11="",""," <- "&IFERROR(INDEX($B:$B,MATCH(AG11,$A:$A,0)),AG11)))))&IF(ISNUMBER(FIND(",",G11))," (+ other parents)","")) | Q11: =IF(A11="","",IF(AD11="",E11&"",IF(AE11="",IF(IFERROR(INDEX($E:$E,MATCH(AD11,$A:$A,0)),"")="","",INDEX($E:$E,MATCH(AD11,$A:$A,0))),IF(AF11="",IF(IFERROR(INDEX($E:$E,MATCH(AE11,$A:$A,0)),"")="","",INDEX($E:$E,MATCH(AE11,$A:$A,0))),IF(AG11="",IF(IFERROR(INDEX($E:$E,MATCH(AF11,$A:$A,0)),"")="","",INDEX($E:$E,MATCH(AF11,$A:$A,0))),IF(IFERROR(INDEX($E:$E,MATCH(AG11,$A:$A,0)),"")="","",INDEX($E:$E,MATCH(AG11,$A:$A,0)))))))) | R11: =IF(A11="","",COUNTIF(Fields!$D:$D,A11)) | S11: =IF(A11="","",SUMIF(Fields!$D:$D,A11,Fields!$Q:$Q)) | T11: =IF(A11="","",COUNTIF('Product inputs'!$D:$D,A11)) | AD11: =IF(A11="","",IF(IFERROR(INDEX($G:$G,MATCH(A11,$A:$A,0)),"")="","",TRIM(IF(ISNUMBER(FIND(",",IFERROR(INDEX($G:$G,MATCH(A11,$A:$A,0)),""))),LEFT(IFERROR(INDEX($G:$G,MATCH(A11,$A:$A,0)),""),FIND(",",IFERROR(INDEX($G:$G,MATCH(A11,$A:$A,0)),""))-1),IFERROR(INDEX($G:$G,MATCH(A11,$A:$A,0)),""))))) | AE11: =IF(AD11="","",IF(IFERROR(INDEX($G:$G,MATCH(AD11,$A:$A,0)),"")="","",TRIM(IF(ISNUMBER(FIND(",",IFERROR(INDEX($G:$G,MATCH(AD11,$A:$A,0)),""))),LEFT(IFERROR(INDEX($G:$G,MATCH(AD11,$A:$A,0)),""),FIND(",",IFERROR(INDEX($G:$G,MATCH(AD11,$A:$A,0)),""))-1),IFERROR(INDEX($G:$G,MATCH(AD11,$A:$A,0)),""))))) | AF11: =IF(AE11="","",IF(IFERROR(INDEX($G:$G,MATCH(AE11,$A:$A,0)),"")="","",TRIM(IF(ISNUMBER(FIND(",",IFERROR(INDEX($G:$G,MATCH(AE11,$A:$A,0)),""))),LEFT(IFERROR(INDEX($G:$G,MATCH(AE11,$A:$A,0)),""),FIND(",",IFERROR(INDEX($G:$G,MATCH(AE11,$A:$A,0)),""))-1),IFERROR(INDEX($G:$G,MATCH(AE11,$A:$A,0)),""))))) | AG11: =IF(AF11="","",IF(IFERROR(INDEX($G:$G,MATCH(AF11,$A:$A,0)),"")="","",TRIM(IF(ISNUMBER(FIND(",",IFERROR(INDEX($G:$G,MATCH(AF11,$A:$A,0)),""))),LEFT(IFERROR(INDEX($G:$G,MATCH(AF11,$A:$A,0)),""),FIND(",",IFERROR(INDEX($G:$G,MATCH(AF11,$A:$A,0)),""))-1),IFERROR(INDEX($G:$G,MATCH(AF11,$A:$A,0)),"")))))
O12: =IF(A12="","",IF(AD12="",0,IF(AE12="",1,IF(AF12="",2,IF(AG12="",3,"4+"))))) | P12: =IF(A12="","",B12&IF(AD12="",""," <- "&IFERROR(INDEX($B:$B,MATCH(AD12,$A:$A,0)),AD12)&IF(AE12="",""," <- "&IFERROR(INDEX($B:$B,MATCH(AE12,$A:$A,0)),AE12)&IF(AF12="",""," <- "&IFERROR(INDEX($B:$B,MATCH(AF12,$A:$A,0)),AF12)&IF(AG12="",""," <- "&IFERROR(INDEX($B:$B,MATCH(AG12,$A:$A,0)),AG12)))))&IF(ISNUMBER(FIND(",",G12))," (+ other parents)","")) | Q12: =IF(A12="","",IF(AD12="",E12&"",IF(AE12="",IF(IFERROR(INDEX($E:$E,MATCH(AD12,$A:$A,0)),"")="","",INDEX($E:$E,MATCH(AD12,$A:$A,0))),IF(AF12="",IF(IFERROR(INDEX($E:$E,MATCH(AE12,$A:$A,0)),"")="","",INDEX($E:$E,MATCH(AE12,$A:$A,0))),IF(AG12="",IF(IFERROR(INDEX($E:$E,MATCH(AF12,$A:$A,0)),"")="","",INDEX($E:$E,MATCH(AF12,$A:$A,0))),IF(IFERROR(INDEX($E:$E,MATCH(AG12,$A:$A,0)),"")="","",INDEX($E:$E,MATCH(AG12,$A:$A,0)))))))) | R12: =IF(A12="","",COUNTIF(Fields!$D:$D,A12)) | S12: =IF(A12="","",SUMIF(Fields!$D:$D,A12,Fields!$Q:$Q)) | T12: =IF(A12="","",COUNTIF('Product inputs'!$D:$D,A12)) | AD12: =IF(A12="","",IF(IFERROR(INDEX($G:$G,MATCH(A12,$A:$A,0)),"")="","",TRIM(IF(ISNUMBER(FIND(",",IFERROR(INDEX($G:$G,MATCH(A12,$A:$A,0)),""))),LEFT(IFERROR(INDEX($G:$G,MATCH(A12,$A:$A,0)),""),FIND(",",IFERROR(INDEX($G:$G,MATCH(A12,$A:$A,0)),""))-1),IFERROR(INDEX($G:$G,MATCH(A12,$A:$A,0)),""))))) | AE12: =IF(AD12="","",IF(IFERROR(INDEX($G:$G,MATCH(AD12,$A:$A,0)),"")="","",TRIM(IF(ISNUMBER(FIND(",",IFERROR(INDEX($G:$G,MATCH(AD12,$A:$A,0)),""))),LEFT(IFERROR(INDEX($G:$G,MATCH(AD12,$A:$A,0)),""),FIND(",",IFERROR(INDEX($G:$G,MATCH(AD12,$A:$A,0)),""))-1),IFERROR(INDEX($G:$G,MATCH(AD12,$A:$A,0)),""))))) | AF12: =IF(AE12="","",IF(IFERROR(INDEX($G:$G,MATCH(AE12,$A:$A,0)),"")="","",TRIM(IF(ISNUMBER(FIND(",",IFERROR(INDEX($G:$G,MATCH(AE12,$A:$A,0)),""))),LEFT(IFERROR(INDEX($G:$G,MATCH(AE12,$A:$A,0)),""),FIND(",",IFERROR(INDEX($G:$G,MATCH(AE12,$A:$A,0)),""))-1),IFERROR(INDEX($G:$G,MATCH(AE12,$A:$A,0)),""))))) | AG12: =IF(AF12="","",IF(IFERROR(INDEX($G:$G,MATCH(AF12,$A:$A,0)),"")="","",TRIM(IF(ISNUMBER(FIND(",",IFERROR(INDEX($G:$G,MATCH(AF12,$A:$A,0)),""))),LEFT(IFERROR(INDEX($G:$G,MATCH(AF12,$A:$A,0)),""),FIND(",",IFERROR(INDEX($G:$G,MATCH(AF12,$A:$A,0)),""))-1),IFERROR(INDEX($G:$G,MATCH(AF12,$A:$A,0)),"")))))
O13: =IF(A13="","",IF(AD13="",0,IF(AE13="",1,IF(AF13="",2,IF(AG13="",3,"4+"))))) | P13: =IF(A13="","",B13&IF(AD13="",""," <- "&IFERROR(INDEX($B:$B,MATCH(AD13,$A:$A,0)),AD13)&IF(AE13="",""," <- "&IFERROR(INDEX($B:$B,MATCH(AE13,$A:$A,0)),AE13)&IF(AF13="",""," <- "&IFERROR(INDEX($B:$B,MATCH(AF13,$A:$A,0)),AF13)&IF(AG13="",""," <- "&IFERROR(INDEX($B:$B,MATCH(AG13,$A:$A,0)),AG13)))))&IF(ISNUMBER(FIND(",",G13))," (+ other parents)","")) | Q13: =IF(A13="","",IF(AD13="",E13&"",IF(AE13="",IF(IFERROR(INDEX($E:$E,MATCH(AD13,$A:$A,0)),"")="","",INDEX($E:$E,MATCH(AD13,$A:$A,0))),IF(AF13="",IF(IFERROR(INDEX($E:$E,MATCH(AE13,$A:$A,0)),"")="","",INDEX($E:$E,MATCH(AE13,$A:$A,0))),IF(AG13="",IF(IFERROR(INDEX($E:$E,MATCH(AF13,$A:$A,0)),"")="","",INDEX($E:$E,MATCH(AF13,$A:$A,0))),IF(IFERROR(INDEX($E:$E,MATCH(AG13,$A:$A,0)),"")="","",INDEX($E:$E,MATCH(AG13,$A:$A,0)))))))) | R13: =IF(A13="","",COUNTIF(Fields!$D:$D,A13)) | S13: =IF(A13="","",SUMIF(Fields!$D:$D,A13,Fields!$Q:$Q)) | T13: =IF(A13="","",COUNTIF('Product inputs'!$D:$D,A13)) | AD13: =IF(A13="","",IF(IFERROR(INDEX($G:$G,MATCH(A13,$A:$A,0)),"")="","",TRIM(IF(ISNUMBER(FIND(",",IFERROR(INDEX($G:$G,MATCH(A13,$A:$A,0)),""))),LEFT(IFERROR(INDEX($G:$G,MATCH(A13,$A:$A,0)),""),FIND(",",IFERROR(INDEX($G:$G,MATCH(A13,$A:$A,0)),""))-1),IFERROR(INDEX($G:$G,MATCH(A13,$A:$A,0)),""))))) | AE13: =IF(AD13="","",IF(IFERROR(INDEX($G:$G,MATCH(AD13,$A:$A,0)),"")="","",TRIM(IF(ISNUMBER(FIND(",",IFERROR(INDEX($G:$G,MATCH(AD13,$A:$A,0)),""))),LEFT(IFERROR(INDEX($G:$G,MATCH(AD13,$A:$A,0)),""),FIND(",",IFERROR(INDEX($G:$G,MATCH(AD13,$A:$A,0)),""))-1),IFERROR(INDEX($G:$G,MATCH(AD13,$A:$A,0)),""))))) | AF13: =IF(AE13="","",IF(IFERROR(INDEX($G:$G,MATCH(AE13,$A:$A,0)),"")="","",TRIM(IF(ISNUMBER(FIND(",",IFERROR(INDEX($G:$G,MATCH(AE13,$A:$A,0)),""))),LEFT(IFERROR(INDEX($G:$G,MATCH(AE13,$A:$A,0)),""),FIND(",",IFERROR(INDEX($G:$G,MATCH(AE13,$A:$A,0)),""))-1),IFERROR(INDEX($G:$G,MATCH(AE13,$A:$A,0)),""))))) | AG13: =IF(AF13="","",IF(IFERROR(INDEX($G:$G,MATCH(AF13,$A:$A,0)),"")="","",TRIM(IF(ISNUMBER(FIND(",",IFERROR(INDEX($G:$G,MATCH(AF13,$A:$A,0)),""))),LEFT(IFERROR(INDEX($G:$G,MATCH(AF13,$A:$A,0)),""),FIND(",",IFERROR(INDEX($G:$G,MATCH(AF13,$A:$A,0)),""))-1),IFERROR(INDEX($G:$G,MATCH(AF13,$A:$A,0)),"")))))
O14: =IF(A14="","",IF(AD14="",0,IF(AE14="",1,IF(AF14="",2,IF(AG14="",3,"4+"))))) | P14: =IF(A14="","",B14&IF(AD14="",""," <- "&IFERROR(INDEX($B:$B,MATCH(AD14,$A:$A,0)),AD14)&IF(AE14="",""," <- "&IFERROR(INDEX($B:$B,MATCH(AE14,$A:$A,0)),AE14)&IF(AF14="",""," <- "&IFERROR(INDEX($B:$B,MATCH(AF14,$A:$A,0)),AF14)&IF(AG14="",""," <- "&IFERROR(INDEX($B:$B,MATCH(AG14,$A:$A,0)),AG14)))))&IF(ISNUMBER(FIND(",",G14))," (+ other parents)","")) | Q14: =IF(A14="","",IF(AD14="",E14&"",IF(AE14="",IF(IFERROR(INDEX($E:$E,MATCH(AD14,$A:$A,0)),"")="","",INDEX($E:$E,MATCH(AD14,$A:$A,0))),IF(AF14="",IF(IFERROR(INDEX($E:$E,MATCH(AE14,$A:$A,0)),"")="","",INDEX($E:$E,MATCH(AE14,$A:$A,0))),IF(AG14="",IF(IFERROR(INDEX($E:$E,MATCH(AF14,$A:$A,0)),"")="","",INDEX($E:$E,MATCH(AF14,$A:$A,0))),IF(IFERROR(INDEX($E:$E,MATCH(AG14,$A:$A,0)),"")="","",INDEX($E:$E,MATCH(AG14,$A:$A,0)))))))) | R14: =IF(A14="","",COUNTIF(Fields!$D:$D,A14)) | S14: =IF(A14="","",SUMIF(Fields!$D:$D,A14,Fields!$Q:$Q)) | T14: =IF(A14="","",COUNTIF('Product inputs'!$D:$D,A14)) | AD14: =IF(A14="","",IF(IFERROR(INDEX($G:$G,MATCH(A14,$A:$A,0)),"")="","",TRIM(IF(ISNUMBER(FIND(",",IFERROR(INDEX($G:$G,MATCH(A14,$A:$A,0)),""))),LEFT(IFERROR(INDEX($G:$G,MATCH(A14,$A:$A,0)),""),FIND(",",IFERROR(INDEX($G:$G,MATCH(A14,$A:$A,0)),""))-1),IFERROR(INDEX($G:$G,MATCH(A14,$A:$A,0)),""))))) | AE14: =IF(AD14="","",IF(IFERROR(INDEX($G:$G,MATCH(AD14,$A:$A,0)),"")="","",TRIM(IF(ISNUMBER(FIND(",",IFERROR(INDEX($G:$G,MATCH(AD14,$A:$A,0)),""))),LEFT(IFERROR(INDEX($G:$G,MATCH(AD14,$A:$A,0)),""),FIND(",",IFERROR(INDEX($G:$G,MATCH(AD14,$A:$A,0)),""))-1),IFERROR(INDEX($G:$G,MATCH(AD14,$A:$A,0)),""))))) | AF14: =IF(AE14="","",IF(IFERROR(INDEX($G:$G,MATCH(AE14,$A:$A,0)),"")="","",TRIM(IF(ISNUMBER(FIND(",",IFERROR(INDEX($G:$G,MATCH(AE14,$A:$A,0)),""))),LEFT(IFERROR(INDEX($G:$G,MATCH(AE14,$A:$A,0)),""),FIND(",",IFERROR(INDEX($G:$G,MATCH(AE14,$A:$A,0)),""))-1),IFERROR(INDEX($G:$G,MATCH(AE14,$A:$A,0)),""))))) | AG14: =IF(AF14="","",IF(IFERROR(INDEX($G:$G,MATCH(AF14,$A:$A,0)),"")="","",TRIM(IF(ISNUMBER(FIND(",",IFERROR(INDEX($G:$G,MATCH(AF14,$A:$A,0)),""))),LEFT(IFERROR(INDEX($G:$G,MATCH(AF14,$A:$A,0)),""),FIND(",",IFERROR(INDEX($G:$G,MATCH(AF14,$A:$A,0)),""))-1),IFERROR(INDEX($G:$G,MATCH(AF14,$A:$A,0)),"")))))
O15: =IF(A15="","",IF(AD15="",0,IF(AE15="",1,IF(AF15="",2,IF(AG15="",3,"4+"))))) | P15: =IF(A15="","",B15&IF(AD15="",""," <- "&IFERROR(INDEX($B:$B,MATCH(AD15,$A:$A,0)),AD15)&IF(AE15="",""," <- "&IFERROR(INDEX($B:$B,MATCH(AE15,$A:$A,0)),AE15)&IF(AF15="",""," <- "&IFERROR(INDEX($B:$B,MATCH(AF15,$A:$A,0)),AF15)&IF(AG15="",""," <- "&IFERROR(INDEX($B:$B,MATCH(AG15,$A:$A,0)),AG15)))))&IF(ISNUMBER(FIND(",",G15))," (+ other parents)","")) | Q15: =IF(A15="","",IF(AD15="",E15&"",IF(AE15="",IF(IFERROR(INDEX($E:$E,MATCH(AD15,$A:$A,0)),"")="","",INDEX($E:$E,MATCH(AD15,$A:$A,0))),IF(AF15="",IF(IFERROR(INDEX($E:$E,MATCH(AE15,$A:$A,0)),"")="","",INDEX($E:$E,MATCH(AE15,$A:$A,0))),IF(AG15="",IF(IFERROR(INDEX($E:$E,MATCH(AF15,$A:$A,0)),"")="","",INDEX($E:$E,MATCH(AF15,$A:$A,0))),IF(IFERROR(INDEX($E:$E,MATCH(AG15,$A:$A,0)),"")="","",INDEX($E:$E,MATCH(AG15,$A:$A,0)))))))) | R15: =IF(A15="","",COUNTIF(Fields!$D:$D,A15)) | S15: =IF(A15="","",SUMIF(Fields!$D:$D,A15,Fields!$Q:$Q)) | T15: =IF(A15="","",COUNTIF('Product inputs'!$D:$D,A15)) | AD15: =IF(A15="","",IF(IFERROR(INDEX($G:$G,MATCH(A15,$A:$A,0)),"")="","",TRIM(IF(ISNUMBER(FIND(",",IFERROR(INDEX($G:$G,MATCH(A15,$A:$A,0)),""))),LEFT(IFERROR(INDEX($G:$G,MATCH(A15,$A:$A,0)),""),FIND(",",IFERROR(INDEX($G:$G,MATCH(A15,$A:$A,0)),""))-1),IFERROR(INDEX($G:$G,MATCH(A15,$A:$A,0)),""))))) | AE15: =IF(AD15="","",IF(IFERROR(INDEX($G:$G,MATCH(AD15,$A:$A,0)),"")="","",TRIM(IF(ISNUMBER(FIND(",",IFERROR(INDEX($G:$G,MATCH(AD15,$A:$A,0)),""))),LEFT(IFERROR(INDEX($G:$G,MATCH(AD15,$A:$A,0)),""),FIND(",",IFERROR(INDEX($G:$G,MATCH(AD15,$A:$A,0)),""))-1),IFERROR(INDEX($G:$G,MATCH(AD15,$A:$A,0)),""))))) | AF15: =IF(AE15="","",IF(IFERROR(INDEX($G:$G,MATCH(AE15,$A:$A,0)),"")="","",TRIM(IF(ISNUMBER(FIND(",",IFERROR(INDEX($G:$G,MATCH(AE15,$A:$A,0)),""))),LEFT(IFERROR(INDEX($G:$G,MATCH(AE15,$A:$A,0)),""),FIND(",",IFERROR(INDEX($G:$G,MATCH(AE15,$A:$A,0)),""))-1),IFERROR(INDEX($G:$G,MATCH(AE15,$A:$A,0)),""))))) | AG15: =IF(AF15="","",IF(IFERROR(INDEX($G:$G,MATCH(AF15,$A:$A,0)),"")="","",TRIM(IF(ISNUMBER(FIND(",",IFERROR(INDEX($G:$G,MATCH(AF15,$A:$A,0)),""))),LEFT(IFERROR(INDEX($G:$G,MATCH(AF15,$A:$A,0)),""),FIND(",",IFERROR(INDEX($G:$G,MATCH(AF15,$A:$A,0)),""))-1),IFERROR(INDEX($G:$G,MATCH(AF15,$A:$A,0)),"")))))
O16: =IF(A16="","",IF(AD16="",0,IF(AE16="",1,IF(AF16="",2,IF(AG16="",3,"4+"))))) | P16: =IF(A16="","",B16&IF(AD16="",""," <- "&IFERROR(INDEX($B:$B,MATCH(AD16,$A:$A,0)),AD16)&IF(AE16="",""," <- "&IFERROR(INDEX($B:$B,MATCH(AE16,$A:$A,0)),AE16)&IF(AF16="",""," <- "&IFERROR(INDEX($B:$B,MATCH(AF16,$A:$A,0)),AF16)&IF(AG16="",""," <- "&IFERROR(INDEX($B:$B,MATCH(AG16,$A:$A,0)),AG16)))))&IF(ISNUMBER(FIND(",",G16))," (+ other parents)","")) | Q16: =IF(A16="","",IF(AD16="",E16&"",IF(AE16="",IF(IFERROR(INDEX($E:$E,MATCH(AD16,$A:$A,0)),"")="","",INDEX($E:$E,MATCH(AD16,$A:$A,0))),IF(AF16="",IF(IFERROR(INDEX($E:$E,MATCH(AE16,$A:$A,0)),"")="","",INDEX($E:$E,MATCH(AE16,$A:$A,0))),IF(AG16="",IF(IFERROR(INDEX($E:$E,MATCH(AF16,$A:$A,0)),"")="","",INDEX($E:$E,MATCH(AF16,$A:$A,0))),IF(IFERROR(INDEX($E:$E,MATCH(AG16,$A:$A,0)),"")="","",INDEX($E:$E,MATCH(AG16,$A:$A,0)))))))) | R16: =IF(A16="","",COUNTIF(Fields!$D:$D,A16)) | S16: =IF(A16="","",SUMIF(Fields!$D:$D,A16,Fields!$Q:$Q)) | T16: =IF(A16="","",COUNTIF('Product inputs'!$D:$D,A16)) | AD16: =IF(A16="","",IF(IFERROR(INDEX($G:$G,MATCH(A16,$A:$A,0)),"")="","",TRIM(IF(ISNUMBER(FIND(",",IFERROR(INDEX($G:$G,MATCH(A16,$A:$A,0)),""))),LEFT(IFERROR(INDEX($G:$G,MATCH(A16,$A:$A,0)),""),FIND(",",IFERROR(INDEX($G:$G,MATCH(A16,$A:$A,0)),""))-1),IFERROR(INDEX($G:$G,MATCH(A16,$A:$A,0)),""))))) | AE16: =IF(AD16="","",IF(IFERROR(INDEX($G:$G,MATCH(AD16,$A:$A,0)),"")="","",TRIM(IF(ISNUMBER(FIND(",",IFERROR(INDEX($G:$G,MATCH(AD16,$A:$A,0)),""))),LEFT(IFERROR(INDEX($G:$G,MATCH(AD16,$A:$A,0)),""),FIND(",",IFERROR(INDEX($G:$G,MATCH(AD16,$A:$A,0)),""))-1),IFERROR(INDEX($G:$G,MATCH(AD16,$A:$A,0)),""))))) | AF16: =IF(AE16="","",IF(IFERROR(INDEX($G:$G,MATCH(AE16,$A:$A,0)),"")="","",TRIM(IF(ISNUMBER(FIND(",",IFERROR(INDEX($G:$G,MATCH(AE16,$A:$A,0)),""))),LEFT(IFERROR(INDEX($G:$G,MATCH(AE16,$A:$A,0)),""),FIND(",",IFERROR(INDEX($G:$G,MATCH(AE16,$A:$A,0)),""))-1),IFERROR(INDEX($G:$G,MATCH(AE16,$A:$A,0)),""))))) | AG16: =IF(AF16="","",IF(IFERROR(INDEX($G:$G,MATCH(AF16,$A:$A,0)),"")="","",TRIM(IF(ISNUMBER(FIND(",",IFERROR(INDEX($G:$G,MATCH(AF16,$A:$A,0)),""))),LEFT(IFERROR(INDEX($G:$G,MATCH(AF16,$A:$A,0)),""),FIND(",",IFERROR(INDEX($G:$G,MATCH(AF16,$A:$A,0)),""))-1),IFERROR(INDEX($G:$G,MATCH(AF16,$A:$A,0)),"")))))
... O304: =IF(A304="","",IF(AD304="",0,IF(AE304="",1,IF(AF304="",2,IF(AG304="",3,"4+"))))) | P304: =IF(A304="","",B304&IF(AD304="",""," <- "&IFERROR(INDEX($B:$B,MATCH(AD304,$A:$A,0)),AD304)&IF(AE304="",""," <- "&IFERROR(INDEX($B:$B,MATCH(AE304,$A:$A,0)),AE304)&IF(AF304="",""," <- "&IFERROR(INDEX($B:$B,MATCH(AF304,$A:$A,0)),AF304)&IF(AG304="",""," <- "&IFERROR(INDEX($B:$B,MATCH(AG304,$A:$A,0)),AG304)))))&IF(ISNUMBER(FIND(",",G304))," (+ other parents)","")) | Q304: =IF(A304="","",IF(AD304="",E304&"",IF(AE304="",IF(IFERROR(INDEX($E:$E,MATCH(AD304,$A:$A,0)),"")="","",INDEX($E:$E,MATCH(AD304,$A:$A,0))),IF(AF304="",IF(IFERROR(INDEX($E:$E,MATCH(AE304,$A:$A,0)),"")="","",INDEX($E:$E,MATCH(AE304,$A:$A,0))),IF(AG304="",IF(IFERROR(INDEX($E:$E,MATCH(AF304,$A:$A,0)),"")="","",INDEX($E:$E,MATCH(AF304,$A:$A,0))),IF(IFERROR(INDEX($E:$E,MATCH(AG304,$A:$A,0)),"")="","",INDEX($E:$E,MATCH(AG304,$A:$A,0)))))))) | R304: =IF(A304="","",COUNTIF(Fields!$D:$D,A304)) | S304: =IF(A304="","",SUMIF(Fields!$D:$D,A304,Fields!$Q:$Q)) | T304: =IF(A304="","",COUNTIF('Product inputs'!$D:$D,A304)) | AD304: =IF(A304="","",IF(IFERROR(INDEX($G:$G,MATCH(A304,$A:$A,0)),"")="","",TRIM(IF(ISNUMBER(FIND(",",IFERROR(INDEX($G:$G,MATCH(A304,$A:$A,0)),""))),LEFT(IFERROR(INDEX($G:$G,MATCH(A304,$A:$A,0)),""),FIND(",",IFERROR(INDEX($G:$G,MATCH(A304,$A:$A,0)),""))-1),IFERROR(INDEX($G:$G,MATCH(A304,$A:$A,0)),""))))) | AE304: =IF(AD304="","",IF(IFERROR(INDEX($G:$G,MATCH(AD304,$A:$A,0)),"")="","",TRIM(IF(ISNUMBER(FIND(",",IFERROR(INDEX($G:$G,MATCH(AD304,$A:$A,0)),""))),LEFT(IFERROR(INDEX($G:$G,MATCH(AD304,$A:$A,0)),""),FIND(",",IFERROR(INDEX($G:$G,MATCH(AD304,$A:$A,0)),""))-1),IFERROR(INDEX($G:$G,MATCH(AD304,$A:$A,0)),""))))) | AF304: =IF(AE304="","",IF(IFERROR(INDEX($G:$G,MATCH(AE304,$A:$A,0)),"")="","",TRIM(IF(ISNUMBER(FIND(",",IFERROR(INDEX($G:$G,MATCH(AE304,$A:$A,0)),""))),LEFT(IFERROR(INDEX($G:$G,MATCH(AE304,$A:$A,0)),""),FIND(",",IFERROR(INDEX($G:$G,MATCH(AE304,$A:$A,0)),""))-1),IFERROR(INDEX($G:$G,MATCH(AE304,$A:$A,0)),""))))) | AG304: =IF(AF304="","",IF(IFERROR(INDEX($G:$G,MATCH(AF304,$A:$A,0)),"")="","",TRIM(IF(ISNUMBER(FIND(",",IFERROR(INDEX($G:$G,MATCH(AF304,$A:$A,0)),""))),LEFT(IFERROR(INDEX($G:$G,MATCH(AF304,$A:$A,0)),""),FIND(",",IFERROR(INDEX($G:$G,MATCH(AF304,$A:$A,0)),""))-1),IFERROR(INDEX($G:$G,MATCH(AF304,$A:$A,0)),"")))))

Sheet Scripts
A1: Scripts
A2: Every notebook, SQL file, workflow or by-hand process that moves data: what it reads, what it writes, what product it feeds, when it runs and who finds out when it fails.
A4: Script ID | B4: Short name | C4: Kind | D4: Path or location | E4: Reads | F4: h_reads_ids | G4: Writes | H4: h_writes_ids | I4: Feeds | J4: h_feeds_ids | K4: What it does | L4: Schedule | M4: Trigger | N4: Who runs it | O4: Failure notice | P4: Last modified | Q4: Notes | R4: Review | S4: Source (where found) | T4: Confidence | U4: Last verified | V4: Verified by
K5: =IF(A5="","",IF(AND(H5<>"",J5<>""),"Both",IF(H5<>"","Builds a table",IF(J5<>"","Feeds a product","Nothing recorded"))))
K6: =IF(A6="","",IF(AND(H6<>"",J6<>""),"Both",IF(H6<>"","Builds a table",IF(J6<>"","Feeds a product","Nothing recorded"))))
K7: =IF(A7="","",IF(AND(H7<>"",J7<>""),"Both",IF(H7<>"","Builds a table",IF(J7<>"","Feeds a product","Nothing recorded"))))
K8: =IF(A8="","",IF(AND(H8<>"",J8<>""),"Both",IF(H8<>"","Builds a table",IF(J8<>"","Feeds a product","Nothing recorded"))))
K9: =IF(A9="","",IF(AND(H9<>"",J9<>""),"Both",IF(H9<>"","Builds a table",IF(J9<>"","Feeds a product","Nothing recorded"))))
K10: =IF(A10="","",IF(AND(H10<>"",J10<>""),"Both",IF(H10<>"","Builds a table",IF(J10<>"","Feeds a product","Nothing recorded"))))
K11: =IF(A11="","",IF(AND(H11<>"",J11<>""),"Both",IF(H11<>"","Builds a table",IF(J11<>"","Feeds a product","Nothing recorded"))))
K12: =IF(A12="","",IF(AND(H12<>"",J12<>""),"Both",IF(H12<>"","Builds a table",IF(J12<>"","Feeds a product","Nothing recorded"))))
K13: =IF(A13="","",IF(AND(H13<>"",J13<>""),"Both",IF(H13<>"","Builds a table",IF(J13<>"","Feeds a product","Nothing recorded"))))
