Workbook

Sheet README
A1: TA metric map
A2: The audit of what exists today, and where each piece lands in the proposed architecture. Fill the lists; the Decisions sheet reads them back as choices.
A4: How it fits together
A5: Products | B5: What people look at: scorecard, dashboards, reports that get sent, data pulls. One row per product.
A6: Metrics | B6: What is measured. One row per distinct definition. Variants of the same idea share a Metric family.
A7: Metric to Product | B7: Which products show which metrics. One row per metric per product.
A8: Populations | B8: The standard reporting populations: who is counted. Defined once here, referenced by every metric.
A9: Tables | B9: Every table we read from or build, what it is built from, why it exists, and how deep in the stack it sits.
A10: Fields | B10: The columns the metrics need. Raw fields come straight from a table. Derived fields carry a business rule in Logic.
A11: Metric to Field | B11: Which fields each metric needs and the role each plays.
A12: Dimensions | B12: The cuts: org, level, location, recruiter. One agreed source each.
A13: Dimension usage | B13: Which products cut by which dimension, using which mapping. Shows where two products slice the same way but from different tables.
A14: Decisions | B14: Read-only. Headline numbers phrased as decisions, each linked to the list of rows behind it.
A15: Decision log | B15: Every agreement, retirement or definition sign-off, with date and who agreed. The record that stops things being relitigated.
A16: Questions | B16: Open questions raised while filling the workbook. Anything uncertain goes here, never into a cell as a guess.
A17: Column guide | B17: Every column on every sheet explained in plain words, with an example. The same text is on each column header as a hover note.
A19: How to fill it in
A20: 1 | B20: Products first. It is the smallest list and everything keys off it.
A21: 2 | B21: Tables: what we read from (HRDW) and what we build (Team custom). Built from gives the lineage; put the main parent first. Why it exists is the column that matters.
A22: 3 | B22: Metrics, one row per distinct definition. Reference a Population ID rather than restating who is counted.
A23: 4 | B23: Fields, pointing each at a Table ID. Derived fields get the rule written in Logic.
A24: 5 | B24: The two join sheets: Metric to Product, Metric to Field. Then Dimensions and Dimension usage.
A25: 6 | B25: Target layer and Disposition on every table and field. This turns the audit into the architecture decision.
A26: 7 | B26: Read Decisions. Record what is agreed in Decision log.
A28: Who fills what
A29: Machine-fillable | B29: Anything visible in a file: products, which tables and fields a dashboard reads, calculated-field logic, lineage from SQL, refresh schedules. A Claude Code skill fills these and tags each row Found, Inferred or Guessed in Confidence.
A30: Human-only | B30: Why a table exists, whether a rule is right, the reporting population, data quality judgement, Target layer, Disposition, Status, points of contact. These stay blank until a person fills them and sets Confidence = Human.
A31: Rule | B31: A blank cell is fine. A guessed cell is a defect. Anything uncertain goes on the Questions sheet.
A33: Colour code
A34: Dark blue header | B34: Column names.
A35: Light blue cells | B35: IDs. Type them; they are the keys that join the sheets.
A36: Cream cells | B36: Free text or dropdowns for people to fill in.
A37: Green text | B37: Formulas. Do not type over them.
A38: Grey cells | B38: Helper columns used by the Decisions sheet. Leave them alone.
A40: Examples | B40: The first rows on each sheet are worked examples around cycle time, hires and recruiter credit. Replace or extend them. Each is marked Example in its notes.

Sheet Decisions
A1: Decisions
A2: Read-only. Each headline is a choice to make; click it to jump to the rows behind it. Counts update as the other sheets are filled.
A4: Decision | B4: Count | C4: What it means | E4: Target layer | F4: Fields | G4: Tables | I4: Disposition | J4: Fields | K4: Tables
A5: =HYPERLINK("#'Decisions'!A16","Tables to retire") -> Tables to retire | B5: =COUNT(Tables!$Z$5:$Z$254) -> 1 | C5: Tables marked Retire, with what still depends on them | E5: Source tables | F5: =COUNTIF(Fields!$J$5:$J$604,E5) -> 8 | G5: =COUNTIF(Tables!$K$5:$K$254,E5) -> 3 | I5: Keep as is | J5: =COUNTIF(Fields!$K$5:$K$604,I5) -> 8 | K5: =COUNTIF(Tables!$L$5:$L$254,I5) -> 4
A6: =HYPERLINK("#'Decisions'!A60","Tables to build") -> Tables to build | B6: =COUNT(Tables!$AA$5:$AA$254) -> 1 | C6: Proposed tables the dispositions call for | E6: Business rules | F6: =COUNTIF(Fields!$J$5:$J$604,E6) -> 2 | G6: =COUNTIF(Tables!$K$5:$K$254,E6) -> 2 | I6: Build | J6: =COUNTIF(Fields!$K$5:$K$604,I6) -> 0 | K6: =COUNTIF(Tables!$L$5:$L$254,I6) -> 1
A7: =HYPERLINK("#'Decisions'!A104","Stacked tables (depth 2 or more)") -> Stacked tables (depth 2 or more) | B7: =COUNT(Tables!$AB$5:$AB$254) -> 2 | C7: Layers built on layers: the simplification candidates | E7: Certified tables | F7: =COUNTIF(Fields!$J$5:$J$604,E7) -> 0 | G7: =COUNTIF(Tables!$K$5:$K$254,E7) -> 1 | I7: Fix upstream | J7: =COUNTIF(Fields!$K$5:$K$604,I7) -> 1 | K7: =COUNTIF(Tables!$L$5:$L$254,I7) -> 0
A8: =HYPERLINK("#'Decisions'!A148","Metric families with more than one definition") -> Metric families with more than one definition | B8: =COUNTIF(Metrics!$S$5:$S$254,">0") -> 2 | C8: Same name, different rule: the alignment agenda with TAAA | E8: Reporting | F8: =COUNTIF(Fields!$J$5:$J$604,E8) -> 0 | G8: =COUNTIF(Tables!$K$5:$K$254,E8) -> 1 | I8: Move to business rules | J8: =COUNTIF(Fields!$K$5:$K$604,I8) -> 1 | K8: =COUNTIF(Tables!$L$5:$L$254,I8) -> 0
A9: =HYPERLINK("#'Decisions'!A192","Fields to fix upstream") -> Fields to fix upstream | B9: =COUNT(Fields!$T$5:$T$604) -> 1 | C9: Data problems that belong to the source, to take to PDP | E9: Not yet assigned | F9: =COUNTA(Fields!$A$5:$A$604)-SUM(F5:F8) -> 0 | G9: =COUNTA(Tables!$A$5:$A$254)-SUM(G5:G8) -> 0 | I9: Merge into certified table | J9: =COUNTIF(Fields!$K$5:$K$604,I9) -> 0 | K9: =COUNTIF(Tables!$L$5:$L$254,I9) -> 1
A10: =HYPERLINK("#'Decisions'!A236","Rules moving into the business layer") -> Rules moving into the business layer | B10: =COUNT(Fields!$U$5:$U$604) -> 1 | C10: Logic that lives in a dashboard or a one-off table today | I10: Retire | J10: =COUNTIF(Fields!$K$5:$K$604,I10) -> 0 | K10: =COUNTIF(Tables!$L$5:$L$254,I10) -> 1
A11: =HYPERLINK("#'Decisions'!A280","Dimension usages off the agreed source") -> Dimension usages off the agreed source | B11: =COUNT('Dimension usage'!$K$5:$K$404) -> 1 | C11: Same filter name, different mapping table | I11: Undecided | J11: =COUNTIF(Fields!$K$5:$K$604,I11) -> 0 | K11: =COUNTIF(Tables!$L$5:$L$254,I11) -> 0
A12: =HYPERLINK("#'Decisions'!A324","Tables and fields still undecided") -> Tables and fields still undecided | B12: =COUNT(Tables!$AC$5:$AC$254)+COUNT(Fields!$V$5:$V$604) -> 0 | C12: No Target layer or Disposition yet
A16: Tables to retire
A17: Tables marked Retire, with what still depends on them. Back to top: | C17: =HYPERLINK("#'Decisions'!A1","top") -> top
A18: Table ID | B18: Table name | C18: Layer | D18: Depth | E18: Metrics depending | F18: Why it exists
A19: =IFERROR(INDEX(Tables!$A$5:$A$254,MATCH(1,Tables!$Z$5:$Z$254,0))&"","") -> T-006 | B19: =IFERROR(INDEX(Tables!$B$5:$B$254,MATCH(1,Tables!$Z$5:$Z$254,0))&"","") -> Recruiter view extract | C19: =IFERROR(INDEX(Tables!$C$5:$C$254,MATCH(1,Tables!$Z$5:$Z$254,0))&"","") -> Team custom | D19: =IFERROR(INDEX(Tables!$M$5:$M$254,MATCH(1,Tables!$Z$5:$Z$254,0)),"") -> 3 | E19: =IFERROR(INDEX(Tables!$P$5:$P$254,MATCH(1,Tables!$Z$5:$Z$254,0)),"") -> 0 | F19: =IFERROR(INDEX(Tables!$E$5:$E$254,MATCH(1,Tables!$Z$5:$Z$254,0))&"","") -> Narrow copy of the recruiter base shaped for the Tableau extract.
A20: =IFERROR(INDEX(Tables!$A$5:$A$254,MATCH(2,Tables!$Z$5:$Z$254,0))&"","") | B20: =IFERROR(INDEX(Tables!$B$5:$B$254,MATCH(2,Tables!$Z$5:$Z$254,0))&"","") | C20: =IFERROR(INDEX(Tables!$C$5:$C$254,MATCH(2,Tables!$Z$5:$Z$254,0))&"","") | D20: =IFERROR(INDEX(Tables!$M$5:$M$254,MATCH(2,Tables!$Z$5:$Z$254,0)),"") | E20: =IFERROR(INDEX(Tables!$P$5:$P$254,MATCH(2,Tables!$Z$5:$Z$254,0)),"") | F20: =IFERROR(INDEX(Tables!$E$5:$E$254,MATCH(2,Tables!$Z$5:$Z$254,0))&"","")
A21: =IFERROR(INDEX(Tables!$A$5:$A$254,MATCH(3,Tables!$Z$5:$Z$254,0))&"","") | B21: =IFERROR(INDEX(Tables!$B$5:$B$254,MATCH(3,Tables!$Z$5:$Z$254,0))&"","") | C21: =IFERROR(INDEX(Tables!$C$5:$C$254,MATCH(3,Tables!$Z$5:$Z$254,0))&"","") | D21: =IFERROR(INDEX(Tables!$M$5:$M$254,MATCH(3,Tables!$Z$5:$Z$254,0)),"") | E21: =IFERROR(INDEX(Tables!$P$5:$P$254,MATCH(3,Tables!$Z$5:$Z$254,0)),"") | F21: =IFERROR(INDEX(Tables!$E$5:$E$254,MATCH(3,Tables!$Z$5:$Z$254,0))&"","")
A22: =IFERROR(INDEX(Tables!$A$5:$A$254,MATCH(4,Tables!$Z$5:$Z$254,0))&"","") | B22: =IFERROR(INDEX(Tables!$B$5:$B$254,MATCH(4,Tables!$Z$5:$Z$254,0))&"","") | C22: =IFERROR(INDEX(Tables!$C$5:$C$254,MATCH(4,Tables!$Z$5:$Z$254,0))&"","") | D22: =IFERROR(INDEX(Tables!$M$5:$M$254,MATCH(4,Tables!$Z$5:$Z$254,0)),"") | E22: =IFERROR(INDEX(Tables!$P$5:$P$254,MATCH(4,Tables!$Z$5:$Z$254,0)),"") | F22: =IFERROR(INDEX(Tables!$E$5:$E$254,MATCH(4,Tables!$Z$5:$Z$254,0))&"","")
A23: =IFERROR(INDEX(Tables!$A$5:$A$254,MATCH(5,Tables!$Z$5:$Z$254,0))&"","") | B23: =IFERROR(INDEX(Tables!$B$5:$B$254,MATCH(5,Tables!$Z$5:$Z$254,0))&"","") | C23: =IFERROR(INDEX(Tables!$C$5:$C$254,MATCH(5,Tables!$Z$5:$Z$254,0))&"","") | D23: =IFERROR(INDEX(Tables!$M$5:$M$254,MATCH(5,Tables!$Z$5:$Z$254,0)),"") | E23: =IFERROR(INDEX(Tables!$P$5:$P$254,MATCH(5,Tables!$Z$5:$Z$254,0)),"") | F23: =IFERROR(INDEX(Tables!$E$5:$E$254,MATCH(5,Tables!$Z$5:$Z$254,0))&"","")
A24: =IFERROR(INDEX(Tables!$A$5:$A$254,MATCH(6,Tables!$Z$5:$Z$254,0))&"","") | B24: =IFERROR(INDEX(Tables!$B$5:$B$254,MATCH(6,Tables!$Z$5:$Z$254,0))&"","") | C24: =IFERROR(INDEX(Tables!$C$5:$C$254,MATCH(6,Tables!$Z$5:$Z$254,0))&"","") | D24: =IFERROR(INDEX(Tables!$M$5:$M$254,MATCH(6,Tables!$Z$5:$Z$254,0)),"") | E24: =IFERROR(INDEX(Tables!$P$5:$P$254,MATCH(6,Tables!$Z$5:$Z$254,0)),"") | F24: =IFERROR(INDEX(Tables!$E$5:$E$254,MATCH(6,Tables!$Z$5:$Z$254,0))&"","")
A25: =IFERROR(INDEX(Tables!$A$5:$A$254,MATCH(7,Tables!$Z$5:$Z$254,0))&"","") | B25: =IFERROR(INDEX(Tables!$B$5:$B$254,MATCH(7,Tables!$Z$5:$Z$254,0))&"","") | C25: =IFERROR(INDEX(Tables!$C$5:$C$254,MATCH(7,Tables!$Z$5:$Z$254,0))&"","") | D25: =IFERROR(INDEX(Tables!$M$5:$M$254,MATCH(7,Tables!$Z$5:$Z$254,0)),"") | E25: =IFERROR(INDEX(Tables!$P$5:$P$254,MATCH(7,Tables!$Z$5:$Z$254,0)),"") | F25: =IFERROR(INDEX(Tables!$E$5:$E$254,MATCH(7,Tables!$Z$5:$Z$254,0))&"","")
A26: =IFERROR(INDEX(Tables!$A$5:$A$254,MATCH(8,Tables!$Z$5:$Z$254,0))&"","") | B26: =IFERROR(INDEX(Tables!$B$5:$B$254,MATCH(8,Tables!$Z$5:$Z$254,0))&"","") | C26: =IFERROR(INDEX(Tables!$C$5:$C$254,MATCH(8,Tables!$Z$5:$Z$254,0))&"","") | D26: =IFERROR(INDEX(Tables!$M$5:$M$254,MATCH(8,Tables!$Z$5:$Z$254,0)),"") | E26: =IFERROR(INDEX(Tables!$P$5:$P$254,MATCH(8,Tables!$Z$5:$Z$254,0)),"") | F26: =IFERROR(INDEX(Tables!$E$5:$E$254,MATCH(8,Tables!$Z$5:$Z$254,0))&"","")
A27: =IFERROR(INDEX(Tables!$A$5:$A$254,MATCH(9,Tables!$Z$5:$Z$254,0))&"","") | B27: =IFERROR(INDEX(Tables!$B$5:$B$254,MATCH(9,Tables!$Z$5:$Z$254,0))&"","") | C27: =IFERROR(INDEX(Tables!$C$5:$C$254,MATCH(9,Tables!$Z$5:$Z$254,0))&"","") | D27: =IFERROR(INDEX(Tables!$M$5:$M$254,MATCH(9,Tables!$Z$5:$Z$254,0)),"") | E27: =IFERROR(INDEX(Tables!$P$5:$P$254,MATCH(9,Tables!$Z$5:$Z$254,0)),"") | F27: =IFERROR(INDEX(Tables!$E$5:$E$254,MATCH(9,Tables!$Z$5:$Z$254,0))&"","")
A28: =IFERROR(INDEX(Tables!$A$5:$A$254,MATCH(10,Tables!$Z$5:$Z$254,0))&"","") | B28: =IFERROR(INDEX(Tables!$B$5:$B$254,MATCH(10,Tables!$Z$5:$Z$254,0))&"","") | C28: =IFERROR(INDEX(Tables!$C$5:$C$254,MATCH(10,Tables!$Z$5:$Z$254,0))&"","") | D28: =IFERROR(INDEX(Tables!$M$5:$M$254,MATCH(10,Tables!$Z$5:$Z$254,0)),"") | E28: =IFERROR(INDEX(Tables!$P$5:$P$254,MATCH(10,Tables!$Z$5:$Z$254,0)),"") | F28: =IFERROR(INDEX(Tables!$E$5:$E$254,MATCH(10,Tables!$Z$5:$Z$254,0))&"","")
A29: =IFERROR(INDEX(Tables!$A$5:$A$254,MATCH(11,Tables!$Z$5:$Z$254,0))&"","") | B29: =IFERROR(INDEX(Tables!$B$5:$B$254,MATCH(11,Tables!$Z$5:$Z$254,0))&"","") | C29: =IFERROR(INDEX(Tables!$C$5:$C$254,MATCH(11,Tables!$Z$5:$Z$254,0))&"","") | D29: =IFERROR(INDEX(Tables!$M$5:$M$254,MATCH(11,Tables!$Z$5:$Z$254,0)),"") | E29: =IFERROR(INDEX(Tables!$P$5:$P$254,MATCH(11,Tables!$Z$5:$Z$254,0)),"") | F29: =IFERROR(INDEX(Tables!$E$5:$E$254,MATCH(11,Tables!$Z$5:$Z$254,0))&"","")
A30: =IFERROR(INDEX(Tables!$A$5:$A$254,MATCH(12,Tables!$Z$5:$Z$254,0))&"","") | B30: =IFERROR(INDEX(Tables!$B$5:$B$254,MATCH(12,Tables!$Z$5:$Z$254,0))&"","") | C30: =IFERROR(INDEX(Tables!$C$5:$C$254,MATCH(12,Tables!$Z$5:$Z$254,0))&"","") | D30: =IFERROR(INDEX(Tables!$M$5:$M$254,MATCH(12,Tables!$Z$5:$Z$254,0)),"") | E30: =IFERROR(INDEX(Tables!$P$5:$P$254,MATCH(12,Tables!$Z$5:$Z$254,0)),"") | F30: =IFERROR(INDEX(Tables!$E$5:$E$254,MATCH(12,Tables!$Z$5:$Z$254,0))&"","")
A31: =IFERROR(INDEX(Tables!$A$5:$A$254,MATCH(13,Tables!$Z$5:$Z$254,0))&"","") | B31: =IFERROR(INDEX(Tables!$B$5:$B$254,MATCH(13,Tables!$Z$5:$Z$254,0))&"","") | C31: =IFERROR(INDEX(Tables!$C$5:$C$254,MATCH(13,Tables!$Z$5:$Z$254,0))&"","") | D31: =IFERROR(INDEX(Tables!$M$5:$M$254,MATCH(13,Tables!$Z$5:$Z$254,0)),"") | E31: =IFERROR(INDEX(Tables!$P$5:$P$254,MATCH(13,Tables!$Z$5:$Z$254,0)),"") | F31: =IFERROR(INDEX(Tables!$E$5:$E$254,MATCH(13,Tables!$Z$5:$Z$254,0))&"","")
A32: =IFERROR(INDEX(Tables!$A$5:$A$254,MATCH(14,Tables!$Z$5:$Z$254,0))&"","") | B32: =IFERROR(INDEX(Tables!$B$5:$B$254,MATCH(14,Tables!$Z$5:$Z$254,0))&"","") | C32: =IFERROR(INDEX(Tables!$C$5:$C$254,MATCH(14,Tables!$Z$5:$Z$254,0))&"","") | D32: =IFERROR(INDEX(Tables!$M$5:$M$254,MATCH(14,Tables!$Z$5:$Z$254,0)),"") | E32: =IFERROR(INDEX(Tables!$P$5:$P$254,MATCH(14,Tables!$Z$5:$Z$254,0)),"") | F32: =IFERROR(INDEX(Tables!$E$5:$E$254,MATCH(14,Tables!$Z$5:$Z$254,0))&"","")
A33: =IFERROR(INDEX(Tables!$A$5:$A$254,MATCH(15,Tables!$Z$5:$Z$254,0))&"","") | B33: =IFERROR(INDEX(Tables!$B$5:$B$254,MATCH(15,Tables!$Z$5:$Z$254,0))&"","") | C33: =IFERROR(INDEX(Tables!$C$5:$C$254,MATCH(15,Tables!$Z$5:$Z$254,0))&"","") | D33: =IFERROR(INDEX(Tables!$M$5:$M$254,MATCH(15,Tables!$Z$5:$Z$254,0)),"") | E33: =IFERROR(INDEX(Tables!$P$5:$P$254,MATCH(15,Tables!$Z$5:$Z$254,0)),"") | F33: =IFERROR(INDEX(Tables!$E$5:$E$254,MATCH(15,Tables!$Z$5:$Z$254,0))&"","")
A34: =IFERROR(INDEX(Tables!$A$5:$A$254,MATCH(16,Tables!$Z$5:$Z$254,0))&"","") | B34: =IFERROR(INDEX(Tables!$B$5:$B$254,MATCH(16,Tables!$Z$5:$Z$254,0))&"","") | C34: =IFERROR(INDEX(Tables!$C$5:$C$254,MATCH(16,Tables!$Z$5:$Z$254,0))&"","") | D34: =IFERROR(INDEX(Tables!$M$5:$M$254,MATCH(16,Tables!$Z$5:$Z$254,0)),"") | E34: =IFERROR(INDEX(Tables!$P$5:$P$254,MATCH(16,Tables!$Z$5:$Z$254,0)),"") | F34: =IFERROR(INDEX(Tables!$E$5:$E$254,MATCH(16,Tables!$Z$5:$Z$254,0))&"","")
A35: =IFERROR(INDEX(Tables!$A$5:$A$254,MATCH(17,Tables!$Z$5:$Z$254,0))&"","") | B35: =IFERROR(INDEX(Tables!$B$5:$B$254,MATCH(17,Tables!$Z$5:$Z$254,0))&"","") | C35: =IFERROR(INDEX(Tables!$C$5:$C$254,MATCH(17,Tables!$Z$5:$Z$254,0))&"","") | D35: =IFERROR(INDEX(Tables!$M$5:$M$254,MATCH(17,Tables!$Z$5:$Z$254,0)),"") | E35: =IFERROR(INDEX(Tables!$P$5:$P$254,MATCH(17,Tables!$Z$5:$Z$254,0)),"") | F35: =IFERROR(INDEX(Tables!$E$5:$E$254,MATCH(17,Tables!$Z$5:$Z$254,0))&"","")
A36: =IFERROR(INDEX(Tables!$A$5:$A$254,MATCH(18,Tables!$Z$5:$Z$254,0))&"","") | B36: =IFERROR(INDEX(Tables!$B$5:$B$254,MATCH(18,Tables!$Z$5:$Z$254,0))&"","") | C36: =IFERROR(INDEX(Tables!$C$5:$C$254,MATCH(18,Tables!$Z$5:$Z$254,0))&"","") | D36: =IFERROR(INDEX(Tables!$M$5:$M$254,MATCH(18,Tables!$Z$5:$Z$254,0)),"") | E36: =IFERROR(INDEX(Tables!$P$5:$P$254,MATCH(18,Tables!$Z$5:$Z$254,0)),"") | F36: =IFERROR(INDEX(Tables!$E$5:$E$254,MATCH(18,Tables!$Z$5:$Z$254,0))&"","")
A37: =IFERROR(INDEX(Tables!$A$5:$A$254,MATCH(19,Tables!$Z$5:$Z$254,0))&"","") | B37: =IFERROR(INDEX(Tables!$B$5:$B$254,MATCH(19,Tables!$Z$5:$Z$254,0))&"","") | C37: =IFERROR(INDEX(Tables!$C$5:$C$254,MATCH(19,Tables!$Z$5:$Z$254,0))&"","") | D37: =IFERROR(INDEX(Tables!$M$5:$M$254,MATCH(19,Tables!$Z$5:$Z$254,0)),"") | E37: =IFERROR(INDEX(Tables!$P$5:$P$254,MATCH(19,Tables!$Z$5:$Z$254,0)),"") | F37: =IFERROR(INDEX(Tables!$E$5:$E$254,MATCH(19,Tables!$Z$5:$Z$254,0))&"","")
A38: =IFERROR(INDEX(Tables!$A$5:$A$254,MATCH(20,Tables!$Z$5:$Z$254,0))&"","") | B38: =IFERROR(INDEX(Tables!$B$5:$B$254,MATCH(20,Tables!$Z$5:$Z$254,0))&"","") | C38: =IFERROR(INDEX(Tables!$C$5:$C$254,MATCH(20,Tables!$Z$5:$Z$254,0))&"","") | D38: =IFERROR(INDEX(Tables!$M$5:$M$254,MATCH(20,Tables!$Z$5:$Z$254,0)),"") | E38: =IFERROR(INDEX(Tables!$P$5:$P$254,MATCH(20,Tables!$Z$5:$Z$254,0)),"") | F38: =IFERROR(INDEX(Tables!$E$5:$E$254,MATCH(20,Tables!$Z$5:$Z$254,0))&"","")
A39: =IFERROR(INDEX(Tables!$A$5:$A$254,MATCH(21,Tables!$Z$5:$Z$254,0))&"","") | B39: =IFERROR(INDEX(Tables!$B$5:$B$254,MATCH(21,Tables!$Z$5:$Z$254,0))&"","") | C39: =IFERROR(INDEX(Tables!$C$5:$C$254,MATCH(21,Tables!$Z$5:$Z$254,0))&"","") | D39: =IFERROR(INDEX(Tables!$M$5:$M$254,MATCH(21,Tables!$Z$5:$Z$254,0)),"") | E39: =IFERROR(INDEX(Tables!$P$5:$P$254,MATCH(21,Tables!$Z$5:$Z$254,0)),"") | F39: =IFERROR(INDEX(Tables!$E$5:$E$254,MATCH(21,Tables!$Z$5:$Z$254,0))&"","")
A40: =IFERROR(INDEX(Tables!$A$5:$A$254,MATCH(22,Tables!$Z$5:$Z$254,0))&"","") | B40: =IFERROR(INDEX(Tables!$B$5:$B$254,MATCH(22,Tables!$Z$5:$Z$254,0))&"","") | C40: =IFERROR(INDEX(Tables!$C$5:$C$254,MATCH(22,Tables!$Z$5:$Z$254,0))&"","") | D40: =IFERROR(INDEX(Tables!$M$5:$M$254,MATCH(22,Tables!$Z$5:$Z$254,0)),"") | E40: =IFERROR(INDEX(Tables!$P$5:$P$254,MATCH(22,Tables!$Z$5:$Z$254,0)),"") | F40: =IFERROR(INDEX(Tables!$E$5:$E$254,MATCH(22,Tables!$Z$5:$Z$254,0))&"","")
A41: =IFERROR(INDEX(Tables!$A$5:$A$254,MATCH(23,Tables!$Z$5:$Z$254,0))&"","") | B41: =IFERROR(INDEX(Tables!$B$5:$B$254,MATCH(23,Tables!$Z$5:$Z$254,0))&"","") | C41: =IFERROR(INDEX(Tables!$C$5:$C$254,MATCH(23,Tables!$Z$5:$Z$254,0))&"","") | D41: =IFERROR(INDEX(Tables!$M$5:$M$254,MATCH(23,Tables!$Z$5:$Z$254,0)),"") | E41: =IFERROR(INDEX(Tables!$P$5:$P$254,MATCH(23,Tables!$Z$5:$Z$254,0)),"") | F41: =IFERROR(INDEX(Tables!$E$5:$E$254,MATCH(23,Tables!$Z$5:$Z$254,0))&"","")
A42: =IFERROR(INDEX(Tables!$A$5:$A$254,MATCH(24,Tables!$Z$5:$Z$254,0))&"","") | B42: =IFERROR(INDEX(Tables!$B$5:$B$254,MATCH(24,Tables!$Z$5:$Z$254,0))&"","") | C42: =IFERROR(INDEX(Tables!$C$5:$C$254,MATCH(24,Tables!$Z$5:$Z$254,0))&"","") | D42: =IFERROR(INDEX(Tables!$M$5:$M$254,MATCH(24,Tables!$Z$5:$Z$254,0)),"") | E42: =IFERROR(INDEX(Tables!$P$5:$P$254,MATCH(24,Tables!$Z$5:$Z$254,0)),"") | F42: =IFERROR(INDEX(Tables!$E$5:$E$254,MATCH(24,Tables!$Z$5:$Z$254,0))&"","")
A43: =IFERROR(INDEX(Tables!$A$5:$A$254,MATCH(25,Tables!$Z$5:$Z$254,0))&"","") | B43: =IFERROR(INDEX(Tables!$B$5:$B$254,MATCH(25,Tables!$Z$5:$Z$254,0))&"","") | C43: =IFERROR(INDEX(Tables!$C$5:$C$254,MATCH(25,Tables!$Z$5:$Z$254,0))&"","") | D43: =IFERROR(INDEX(Tables!$M$5:$M$254,MATCH(25,Tables!$Z$5:$Z$254,0)),"") | E43: =IFERROR(INDEX(Tables!$P$5:$P$254,MATCH(25,Tables!$Z$5:$Z$254,0)),"") | F43: =IFERROR(INDEX(Tables!$E$5:$E$254,MATCH(25,Tables!$Z$5:$Z$254,0))&"","")
A44: =IFERROR(INDEX(Tables!$A$5:$A$254,MATCH(26,Tables!$Z$5:$Z$254,0))&"","") | B44: =IFERROR(INDEX(Tables!$B$5:$B$254,MATCH(26,Tables!$Z$5:$Z$254,0))&"","") | C44: =IFERROR(INDEX(Tables!$C$5:$C$254,MATCH(26,Tables!$Z$5:$Z$254,0))&"","") | D44: =IFERROR(INDEX(Tables!$M$5:$M$254,MATCH(26,Tables!$Z$5:$Z$254,0)),"") | E44: =IFERROR(INDEX(Tables!$P$5:$P$254,MATCH(26,Tables!$Z$5:$Z$254,0)),"") | F44: =IFERROR(INDEX(Tables!$E$5:$E$254,MATCH(26,Tables!$Z$5:$Z$254,0))&"","")
...

Sheet Column guide
A1: Column guide
A2: What every column means and how to fill it. The same text appears as a hover note on each column header. Columns marked Filled automatically are formulas.
A4: Sheet | B4: Column | C4: What it means and how to fill it | D4: Example
A5: Products | B5: Product ID | C5: A short code you assign: P-001, P-002 and so on. Never changes once given. Other sheets use it to refer to the product. | D5: P-001
A6: Products | B6: Product name | C6: The name people actually use. | D6: TA scorecard
A7: Products | B7: Type | C7: Scorecard = the executive view. Dashboard = a Tableau or QuickSight view people open. Sent report = something emailed or posted on a schedule. Data pull = a recurring extract. Table = a table other teams read directly. | D7: Dashboard
A8: Products | B8: Tool | C8: Where it lives. | D8: Tableau
A9: Products | B9: Audience | C9: Who looks at it. | D9: Recruiting leads
A10: Products | B10: Owner (team) | C10: The team responsible for keeping it working. | D10: Team Opportunity
A11: Products | B11: Point of contact | C11: The person to call about it. Human-only. | D11: A. Patel
A12: Products | B12: Refresh frequency | C12: How often the data behind it updates. For dashboards this is the extract or live refresh schedule. | D12: Daily
A13: Products | B13: Delivery cadence | C13: Sent reports only: when and to whom it goes out. Leave blank for dashboards. | D13: Sent monthly to TA leadership
A14: Products | B14: Notes | C14: Anything else worth knowing. | D14: Often questioned at QBR
A15: Products | B15: Source (where found) | C15: The file or place the row came from: a workbook file name, a repo path, a deck, a conversation. | D15: scorecard.twb
... A26: Populations | B26: Metrics using it | C26: Filled automatically: how many metrics reference this population. | D26: 4
A27: Populations | B27: Notes | C27: Anything else.
A28: Metrics | B28: Metric ID | C28: A short code: M-001, M-002. If the same name is calculated two different ways today, each way gets its own ID. | D28: M-001
A29: Metrics | B29: Metric family | C29: The plain name people use, shared by every variant. All the cycle times are family Cycle time. If a family ends up with more than one definition, it appears on Decisions as something to align. | D29: Cycle time
A30: Metrics | B30: Metric name | C30: The specific name, with the distinguishing part in brackets when there is more than one version. | D30: Cycle time (approved to accepted)
A31: Metrics | B31: Definition (plain words) | C31: How the number is calculated, written so a recruiter would understand it. What starts the clock, what ends it, what happens on a transfer. No SQL. Do not restate who is counted; that is the Population. | D31: Calendar days from approval to offer accepted; transfers keep the original approval date
A32: Metrics | B32: Population ID | C32: Which standard population this metric counts. Pick from the Populations sheet. | D32: POP-001
A33: Metrics | B33: Population | C33: Filled automatically. | D33: Standard requisitions
A34: Metrics | B34: Grain (one row per) | C34: The thing you count or average over. Ask: if I listed this metric line by line, what is each line? A requisition? An opening (one req can have several)? An application? A hire? A req with three openings gives one number per req but three per opening, so this changes the answer. | D34: Opening
A35: Metrics | B35: Unit | C35: Days, count, percent, dollars. | D35: Days
A36: Metrics | B36: Status | C36: Draft = our proposal. Under review = with TAAA. Agreed = both teams signed off. Certified = agreed and built into a certified table. | D36: Draft
A37: Metrics | B37: Owner | C37: Who on our team owns the definition. | D37: A. Patel
A38: Metrics | B38: Products using it | C38: Filled automatically. | D38: 3
A39: Metrics | B39: Fields needed | C39: Filled automatically. | D39: 5
... A46: Metric to Product | B46: How it is shown | C46: What the product does with it: headline tile, trend, table, filter. | D46: Trend by recruiter, monthly
A47: Metric to Product | B47: Notes | C47: Anything else.
A48: Tables | B48: Table ID | C48: A short code: T-001, T-002. | D48: T-004
A49: Tables | B49: Table name | C49: The name as it appears in Snowflake or our documentation. | D49: Requisition linkage table
A50: Tables | B50: Layer | C50: HRDW = a warehouse table we read as delivered. Team custom = a table our team builds on top. Platform = a direct feed from a recruiting system (Workday, Canvas); only used once we hold the source-to-target mapping from PDP. | D50: Team custom
A51: Tables | B51: Built from (table IDs, main parent first) | C51: For Team custom tables: the codes of the tables it reads from, main parent first. Lineage chain follows the first parent, so order matters. | D51: T-004, T-001
A52: Tables | B52: Why it exists | C52: The reason the table was created, in one or two sentences. For HRDW tables, what it is the source of record for. For Team custom tables, what problem it solves that the table below it does not. If nobody can say, write Unknown and set Disposition = Retire. | D52: Maps a transferred req to its original so clocks keep running
A53: Tables | B53: Owner (team) | C53: Team responsible for the table. | D53: Team Opportunity
A54: Tables | B54: Refresh owner | C54: Team that runs the refresh job. Often the same as Owner; not always. | D54: PDP
A55: Tables | B55: Point of contact | C55: The person to call. Human-only. | D55: A. Patel
A56: Tables | B56: Refresh | C56: How often it updates. | D56: Daily
A57: Tables | B57: Status | C57: Active = in use. Proposed = planned, not built. Retire = candidate to remove. Unknown = not sure yet. | D57: Active
...

Sheet Products
A1: Products
A2: One row per thing people look at. ID is the key used on Metric to Product and Dimension usage.
A4: Product ID | B4: Product name | C4: Type | D4: Tool | E4: Audience | F4: Owner (team) | G4: Point of contact | H4: Refresh frequency | I4: Delivery cadence | J4: Notes | K4: Source (where found) | L4: Confidence | M4: Last verified | N4: Verified by
A5: P-001 | B5: TA scorecard | C5: Scorecard | D5: Tableau | E5: Executives | F5: Team Opportunity | H5: Weekly | I5: Sent monthly to TA leadership | J5: Example. One tab per org, same metrics; a few tabs with different metrics. | L5: Human | M5: 2026-10-07
A6: P-002 | B6: Recruiter view | C6: Dashboard | D6: Tableau | E6: Recruiting team | F6: Team Opportunity | H6: Daily | J6: Example. | L6: Human | M6: 2026-10-07
A7: P-003 | B7: Hiring manager view | C7: Dashboard | D7: Tableau | E7: Hiring managers | F7: Team Opportunity | H7: Daily | J7: Example. | L7: Human | M7: 2026-10-07

Sheet Metrics
A1: Metrics
A2: One row per distinct definition. Same idea, different rule = different row, same family. Same rule, different cut = one row (the cut is a dimension).
A4: Metric ID | B4: Metric family | C4: Metric name | D4: Definition (plain words) | E4: Population ID | F4: Population | G4: Grain (one row per) | H4: Unit | I4: Status | J4: Owner | K4: Products using it | L4: Fields needed | M4: Definitions in family | N4: Notes | O4: Source (where found) | P4: Confidence | Q4: Last verified | R4: Verified by | S4: h_conflict
A5: M-001 | B5: Cycle time | C5: Cycle time (approved to accepted) | D5: Calendar days from requisition approval to offer acceptance. If a requisition is transferred, the clock keeps running from the original approval date. | E5: POP-001 | F5: =IF(E5="","",IFERROR(INDEX(Populations!$B:$B,MATCH(E5,Populations!$A:$A,0)),"ID not found")) -> Standard requisitions | G5: Opening | H5: Days | I5: Draft | K5: =IF(A5="","",COUNTIF('Metric to Product'!$A:$A,A5)) -> 2 | L5: =IF(A5="","",COUNTIF('Metric to Field'!$A:$A,A5)) -> 5 | M5: =IF(B5="","",COUNTIF($B$5:$B$254,B5)) -> 2 | N5: Example. Proposed scorecard version. | O5: scorecard.twb | P5: Found | Q5: 2026-10-07 | S5: =IF(AND(A5<>"",M5>1),COUNTIFS($A$5:A5,"<>",$M$5:M5,">1"),"") -> 1
A6: M-002 | B6: Cycle time | C6: Cycle time (posted to start) | D6: Calendar days from the requisition being posted to the new hire's start date. | E6: POP-001 | F6: =IF(E6="","",IFERROR(INDEX(Populations!$B:$B,MATCH(E6,Populations!$A:$A,0)),"ID not found")) -> Standard requisitions | G6: Opening | H6: Days | I6: Draft | K6: =IF(A6="","",COUNTIF('Metric to Product'!$A:$A,A6)) -> 1 | L6: =IF(A6="","",COUNTIF('Metric to Field'!$A:$A,A6)) -> 3 | M6: =IF(B6="","",COUNTIF($B$5:$B$254,B6)) -> 2 | N6: Example. A second clock with the same name, found on the recruiter view. Family has two definitions, so it appears on Decisions. | O6: recruiter_view.twb | P6: Found | Q6: 2026-10-07 | S6: =IF(AND(A6<>"",M6>1),COUNTIFS($A$5:A6,"<>",$M$5:M6,">1"),"") -> 2
A7: M-003 | B7: Hires | C7: Hires | D7: Count of accepted offers in the period. Cut by recruiter, org or level as a dimension; the count itself does not change. | E7: POP-002 | F7: =IF(E7="","",IFERROR(INDEX(Populations!$B:$B,MATCH(E7,Populations!$A:$A,0)),"ID not found")) -> All accepted offers | G7: Hire | H7: Count | I7: Draft | K7: =IF(A7="","",COUNTIF('Metric to Product'!$A:$A,A7)) -> 2 | L7: =IF(A7="","",COUNTIF('Metric to Field'!$A:$A,A7)) -> 2 | M7: =IF(B7="","",COUNTIF($B$5:$B$254,B7)) -> 1 | N7: Example. Hires by recruiter is this metric cut by the recruiter dimension, not a separate metric. | O7: scorecard.twb | P7: Found | Q7: 2026-10-07 | S7: =IF(AND(A7<>"",M7>1),COUNTIFS($A$5:A7,"<>",$M$5:M7,">1"),"")
F8: =IF(E8="","",IFERROR(INDEX(Populations!$B:$B,MATCH(E8,Populations!$A:$A,0)),"ID not found")) | K8: =IF(A8="","",COUNTIF('Metric to Product'!$A:$A,A8)) | L8: =IF(A8="","",COUNTIF('Metric to Field'!$A:$A,A8)) | M8: =IF(B8="","",COUNTIF($B$5:$B$254,B8)) | S8: =IF(AND(A8<>"",M8>1),COUNTIFS($A$5:A8,"<>",$M$5:M8,">1"),"")
F9: =IF(E9="","",IFERROR(INDEX(Populations!$B:$B,MATCH(E9,Populations!$A:$A,0)),"ID not found")) | K9: =IF(A9="","",COUNTIF('Metric to Product'!$A:$A,A9)) | L9: =IF(A9="","",COUNTIF('Metric to Field'!$A:$A,A9)) | M9: =IF(B9="","",COUNTIF($B$5:$B$254,B9)) | S9: =IF(AND(A9<>"",M9>1),COUNTIFS($A$5:A9,"<>",$M$5:M9,">1"),"")
F10: =IF(E10="","",IFERROR(INDEX(Populations!$B:$B,MATCH(E10,Populations!$A:$A,0)),"ID not found")) | K10: =IF(A10="","",COUNTIF('Metric to Product'!$A:$A,A10)) | L10: =IF(A10="","",COUNTIF('Metric to Field'!$A:$A,A10)) | M10: =IF(B10="","",COUNTIF($B$5:$B$254,B10)) | S10: =IF(AND(A10<>"",M10>1),COUNTIFS($A$5:A10,"<>",$M$5:M10,">1"),"")
F11: =IF(E11="","",IFERROR(INDEX(Populations!$B:$B,MATCH(E11,Populations!$A:$A,0)),"ID not found")) | K11: =IF(A11="","",COUNTIF('Metric to Product'!$A:$A,A11)) | L11: =IF(A11="","",COUNTIF('Metric to Field'!$A:$A,A11)) | M11: =IF(B11="","",COUNTIF($B$5:$B$254,B11)) | S11: =IF(AND(A11<>"",M11>1),COUNTIFS($A$5:A11,"<>",$M$5:M11,">1"),"")
F12: =IF(E12="","",IFERROR(INDEX(Populations!$B:$B,MATCH(E12,Populations!$A:$A,0)),"ID not found")) | K12: =IF(A12="","",COUNTIF('Metric to Product'!$A:$A,A12)) | L12: =IF(A12="","",COUNTIF('Metric to Field'!$A:$A,A12)) | M12: =IF(B12="","",COUNTIF($B$5:$B$254,B12)) | S12: =IF(AND(A12<>"",M12>1),COUNTIFS($A$5:A12,"<>",$M$5:M12,">1"),"")
F13: =IF(E13="","",IFERROR(INDEX(Populations!$B:$B,MATCH(E13,Populations!$A:$A,0)),"ID not found")) | K13: =IF(A13="","",COUNTIF('Metric to Product'!$A:$A,A13)) | L13: =IF(A13="","",COUNTIF('Metric to Field'!$A:$A,A13)) | M13: =IF(B13="","",COUNTIF($B$5:$B$254,B13)) | S13: =IF(AND(A13<>"",M13>1),COUNTIFS($A$5:A13,"<>",$M$5:M13,">1"),"")
F14: =IF(E14="","",IFERROR(INDEX(Populations!$B:$B,MATCH(E14,Populations!$A:$A,0)),"ID not found")) | K14: =IF(A14="","",COUNTIF('Metric to Product'!$A:$A,A14)) | L14: =IF(A14="","",COUNTIF('Metric to Field'!$A:$A,A14)) | M14: =IF(B14="","",COUNTIF($B$5:$B$254,B14)) | S14: =IF(AND(A14<>"",M14>1),COUNTIFS($A$5:A14,"<>",$M$5:M14,">1"),"")
F15: =IF(E15="","",IFERROR(INDEX(Populations!$B:$B,MATCH(E15,Populations!$A:$A,0)),"ID not found")) | K15: =IF(A15="","",COUNTIF('Metric to Product'!$A:$A,A15)) | L15: =IF(A15="","",COUNTIF('Metric to Field'!$A:$A,A15)) | M15: =IF(B15="","",COUNTIF($B$5:$B$254,B15)) | S15: =IF(AND(A15<>"",M15>1),COUNTIFS($A$5:A15,"<>",$M$5:M15,">1"),"")
F16: =IF(E16="","",IFERROR(INDEX(Populations!$B:$B,MATCH(E16,Populations!$A:$A,0)),"ID not found")) | K16: =IF(A16="","",COUNTIF('Metric to Product'!$A:$A,A16)) | L16: =IF(A16="","",COUNTIF('Metric to Field'!$A:$A,A16)) | M16: =IF(B16="","",COUNTIF($B$5:$B$254,B16)) | S16: =IF(AND(A16<>"",M16>1),COUNTIFS($A$5:A16,"<>",$M$5:M16,">1"),"")
F17: =IF(E17="","",IFERROR(INDEX(Populations!$B:$B,MATCH(E17,Populations!$A:$A,0)),"ID not found")) | K17: =IF(A17="","",COUNTIF('Metric to Product'!$A:$A,A17)) | L17: =IF(A17="","",COUNTIF('Metric to Field'!$A:$A,A17)) | M17: =IF(B17="","",COUNTIF($B$5:$B$254,B17)) | S17: =IF(AND(A17<>"",M17>1),COUNTIFS($A$5:A17,"<>",$M$5:M17,">1"),"")
F18: =IF(E18="","",IFERROR(INDEX(Populations!$B:$B,MATCH(E18,Populations!$A:$A,0)),"ID not found")) | K18: =IF(A18="","",COUNTIF('Metric to Product'!$A:$A,A18)) | L18: =IF(A18="","",COUNTIF('Metric to Field'!$A:$A,A18)) | M18: =IF(B18="","",COUNTIF($B$5:$B$254,B18)) | S18: =IF(AND(A18<>"",M18>1),COUNTIFS($A$5:A18,"<>",$M$5:M18,">1"),"")
F19: =IF(E19="","",IFERROR(INDEX(Populations!$B:$B,MATCH(E19,Populations!$A:$A,0)),"ID not found")) | K19: =IF(A19="","",COUNTIF('Metric to Product'!$A:$A,A19)) | L19: =IF(A19="","",COUNTIF('Metric to Field'!$A:$A,A19)) | M19: =IF(B19="","",COUNTIF($B$5:$B$254,B19)) | S19: =IF(AND(A19<>"",M19>1),COUNTIFS($A$5:A19,"<>",$M$5:M19,">1"),"")
... F254: =IF(E254="","",IFERROR(INDEX(Populations!$B:$B,MATCH(E254,Populations!$A:$A,0)),"ID not found")) | K254: =IF(A254="","",COUNTIF('Metric to Product'!$A:$A,A254)) | L254: =IF(A254="","",COUNTIF('Metric to Field'!$A:$A,A254)) | M254: =IF(B254="","",COUNTIF($B$5:$B$254,B254)) | S254: =IF(AND(A254<>"",M254>1),COUNTIFS($A$5:A254,"<>",$M$5:M254,">1"),"")

Sheet Metric to Product
A1: Metric to Product
A2: One row per place a metric appears. Type the two IDs; names fill in.
A4: Metric ID | B4: Product ID | C4: Metric name | D4: Product name | E4: How it is shown | F4: Notes | G4: Source (where found) | H4: Confidence
A5: M-001 | B5: P-001 | C5: =IF(A5="","",IFERROR(INDEX(Metrics!$C:$C,MATCH(A5,Metrics!$A:$A,0)),"ID not found")) -> Cycle time (approved to accepted) | D5: =IF(B5="","",IFERROR(INDEX(Products!$B:$B,MATCH(B5,Products!$A:$A,0)),"ID not found")) -> TA scorecard | E5: Headline tile, quarterly average, one tab per org | F5: Example. | G5: scorecard.twb | H5: Found
A6: M-002 | B6: P-002 | C6: =IF(A6="","",IFERROR(INDEX(Metrics!$C:$C,MATCH(A6,Metrics!$A:$A,0)),"ID not found")) -> Cycle time (posted to start) | D6: =IF(B6="","",IFERROR(INDEX(Products!$B:$B,MATCH(B6,Products!$A:$A,0)),"ID not found")) -> Recruiter view | E6: Trend by recruiter, monthly | F6: Example. | G6: recruiter_view.twb | H6: Found
A7: M-001 | B7: P-003 | C7: =IF(A7="","",IFERROR(INDEX(Metrics!$C:$C,MATCH(A7,Metrics!$A:$A,0)),"ID not found")) -> Cycle time (approved to accepted) | D7: =IF(B7="","",IFERROR(INDEX(Products!$B:$B,MATCH(B7,Products!$A:$A,0)),"ID not found")) -> Hiring manager view | E7: Average per hiring manager | F7: Example. | G7: hm_view.twb | H7: Found
A8: M-003 | B8: P-001 | C8: =IF(A8="","",IFERROR(INDEX(Metrics!$C:$C,MATCH(A8,Metrics!$A:$A,0)),"ID not found")) -> Hires | D8: =IF(B8="","",IFERROR(INDEX(Products!$B:$B,MATCH(B8,Products!$A:$A,0)),"ID not found")) -> TA scorecard | E8: Count, one tab per org | F8: Example. | G8: scorecard.twb | H8: Found
A9: M-003 | B9: P-002 | C9: =IF(A9="","",IFERROR(INDEX(Metrics!$C:$C,MATCH(A9,Metrics!$A:$A,0)),"ID not found")) -> Hires | D9: =IF(B9="","",IFERROR(INDEX(Products!$B:$B,MATCH(B9,Products!$A:$A,0)),"ID not found")) -> Recruiter view | E9: Bar by recruiter, quarter to date | F9: Example. | G9: recruiter_view.twb | H9: Found
C10: =IF(A10="","",IFERROR(INDEX(Metrics!$C:$C,MATCH(A10,Metrics!$A:$A,0)),"ID not found")) | D10: =IF(B10="","",IFERROR(INDEX(Products!$B:$B,MATCH(B10,Products!$A:$A,0)),"ID not found"))
C11: =IF(A11="","",IFERROR(INDEX(Metrics!$C:$C,MATCH(A11,Metrics!$A:$A,0)),"ID not found")) | D11: =IF(B11="","",IFERROR(INDEX(Products!$B:$B,MATCH(B11,Products!$A:$A,0)),"ID not found"))
C12: =IF(A12="","",IFERROR(INDEX(Metrics!$C:$C,MATCH(A12,Metrics!$A:$A,0)),"ID not found")) | D12: =IF(B12="","",IFERROR(INDEX(Products!$B:$B,MATCH(B12,Products!$A:$A,0)),"ID not found"))
C13: =IF(A13="","",IFERROR(INDEX(Metrics!$C:$C,MATCH(A13,Metrics!$A:$A,0)),"ID not found")) | D13: =IF(B13="","",IFERROR(INDEX(Products!$B:$B,MATCH(B13,Products!$A:$A,0)),"ID not found"))
C14: =IF(A14="","",IFERROR(INDEX(Metrics!$C:$C,MATCH(A14,Metrics!$A:$A,0)),"ID not found")) | D14: =IF(B14="","",IFERROR(INDEX(Products!$B:$B,MATCH(B14,Products!$A:$A,0)),"ID not found"))
C15: =IF(A15="","",IFERROR(INDEX(Metrics!$C:$C,MATCH(A15,Metrics!$A:$A,0)),"ID not found")) | D15: =IF(B15="","",IFERROR(INDEX(Products!$B:$B,MATCH(B15,Products!$A:$A,0)),"ID not found"))
C16: =IF(A16="","",IFERROR(INDEX(Metrics!$C:$C,MATCH(A16,Metrics!$A:$A,0)),"ID not found")) | D16: =IF(B16="","",IFERROR(INDEX(Products!$B:$B,MATCH(B16,Products!$A:$A,0)),"ID not found"))
C17: =IF(A17="","",IFERROR(INDEX(Metrics!$C:$C,MATCH(A17,Metrics!$A:$A,0)),"ID not found")) | D17: =IF(B17="","",IFERROR(INDEX(Products!$B:$B,MATCH(B17,Products!$A:$A,0)),"ID not found"))
C18: =IF(A18="","",IFERROR(INDEX(Metrics!$C:$C,MATCH(A18,Metrics!$A:$A,0)),"ID not found")) | D18: =IF(B18="","",IFERROR(INDEX(Products!$B:$B,MATCH(B18,Products!$A:$A,0)),"ID not found"))
C19: =IF(A19="","",IFERROR(INDEX(Metrics!$C:$C,MATCH(A19,Metrics!$A:$A,0)),"ID not found")) | D19: =IF(B19="","",IFERROR(INDEX(Products!$B:$B,MATCH(B19,Products!$A:$A,0)),"ID not found"))
C20: =IF(A20="","",IFERROR(INDEX(Metrics!$C:$C,MATCH(A20,Metrics!$A:$A,0)),"ID not found")) | D20: =IF(B20="","",IFERROR(INDEX(Products!$B:$B,MATCH(B20,Products!$A:$A,0)),"ID not found"))
C21: =IF(A21="","",IFERROR(INDEX(Metrics!$C:$C,MATCH(A21,Metrics!$A:$A,0)),"ID not found")) | D21: =IF(B21="","",IFERROR(INDEX(Products!$B:$B,MATCH(B21,Products!$A:$A,0)),"ID not found"))
... C504: =IF(A504="","",IFERROR(INDEX(Metrics!$C:$C,MATCH(A504,Metrics!$A:$A,0)),"ID not found")) | D504: =IF(B504="","",IFERROR(INDEX(Products!$B:$B,MATCH(B504,Products!$A:$A,0)),"ID not found"))

Sheet Populations
A1: Populations
A2: Who is counted. Define each standard reporting population once here; metrics reference the ID instead of restating it.
A4: Population ID | B4: Population name | C4: Definition (plain words) | D4: Includes | E4: Excludes | F4: Status | G4: Owner | H4: Metrics using it | I4: Notes | J4: Source (where found) | K4: Confidence | L4: Last verified | M4: Verified by
A5: POP-001 | B5: Standard requisitions | C5: Requisitions for a named role that go through the normal approval process. | D5: Approved requisitions, internal and external, all levels | E5: Evergreen requisitions, cancelled requisitions, contingent worker requests | F5: Draft | H5: =IF(A5="","",COUNTIF(Metrics!$E:$E,A5)) -> 2 | I5: Example. The population most TA metrics should share. | K5: Human | L5: 2026-10-07
A6: POP-002 | B6: All accepted offers | C6: Every offer accepted in the period, regardless of requisition type. | D6: Internal and external hires | E6: Rescinded offers | F6: Draft | H6: =IF(A6="","",COUNTIF(Metrics!$E:$E,A6)) -> 1 | I6: Example. | K6: Human | L6: 2026-10-07
H7: =IF(A7="","",COUNTIF(Metrics!$E:$E,A7))
H8: =IF(A8="","",COUNTIF(Metrics!$E:$E,A8))
H9: =IF(A9="","",COUNTIF(Metrics!$E:$E,A9))
H10: =IF(A10="","",COUNTIF(Metrics!$E:$E,A10))
H11: =IF(A11="","",COUNTIF(Metrics!$E:$E,A11))
H12: =IF(A12="","",COUNTIF(Metrics!$E:$E,A12))
H13: =IF(A13="","",COUNTIF(Metrics!$E:$E,A13))
H14: =IF(A14="","",COUNTIF(Metrics!$E:$E,A14))
H15: =IF(A15="","",COUNTIF(Metrics!$E:$E,A15))
H16: =IF(A16="","",COUNTIF(Metrics!$E:$E,A16))
H17: =IF(A17="","",COUNTIF(Metrics!$E:$E,A17))
H18: =IF(A18="","",COUNTIF(Metrics!$E:$E,A18))
... H64: =IF(A64="","",COUNTIF(Metrics!$E:$E,A64))

Sheet Tables
A1: Tables
A2: Every table we read from or build. Built from gives the lineage; put the main parent first. Depth and Lineage chain are computed from it.
A4: Table ID | B4: Table name | C4: Layer | D4: Built from (table IDs, main parent first) | E4: Why it exists | F4: Owner (team) | G4: Refresh owner | H4: Point of contact | I4: Refresh | J4: Status | K4: Target layer | L4: Disposition | M4: Depth | N4: Lineage chain | O4: Fields listed | P4: Metrics depending | Q4: Notes | R4: Source (where found) | S4: Confidence | T4: Last verified | U4: Verified by | V4: h_p1 | W4: h_p2 | X4: h_p3 | Y4: h_p4 | Z4: h_retire | AA4: h_build | AB4: h_deep | AC4: h_undecided
A5: T-001 | B5: HRDW requisition table | C5: HRDW | E5: Source of record for requisitions as delivered by the warehouse. | F5: PDP | G5: PDP | I5: Daily | J5: Active | K5: Source tables | L5: Keep as is | M5: =IF(A5="","",IF(V5="",0,IF(W5="",1,IF(X5="",2,IF(Y5="",3,"4+"))))) -> 0 | N5: =IF(A5="","",A5&IF(V5="",""," <- "&V5&IF(W5="",""," <- "&W5&IF(X5="",""," <- "&X5&IF(Y5="",""," <- "&Y5))))&IF(ISNUMBER(FIND(",",D5))," (+ other parents)","")) -> T-001 | O5: =IF(A5="","",COUNTIF(Fields!$D:$D,A5)) -> 4 | P5: =IF(A5="","",SUMIF(Fields!$D:$D,A5,Fields!$O:$O)) -> 8 | Q5: Example. | S5: Human | T5: 2026-10-07 | V5: =IF(A5="","",IF(IFERROR(INDEX($D:$D,MATCH(A5,$A:$A,0)),"")="","",TRIM(IF(ISNUMBER(FIND(",",IFERROR(INDEX($D:$D,MATCH(A5,$A:$A,0)),""))),LEFT(IFERROR(INDEX($D:$D,MATCH(A5,$A:$A,0)),""),FIND(",",IFERROR(INDEX($D:$D,MATCH(A5,$A:$A,0)),""))-1),IFERROR(INDEX($D:$D,MATCH(A5,$A:$A,0)),""))))) | W5: =IF(V5="","",IF(IFERROR(INDEX($D:$D,MATCH(V5,$A:$A,0)),"")="","",TRIM(IF(ISNUMBER(FIND(",",IFERROR(INDEX($D:$D,MATCH(V5,$A:$A,0)),""))),LEFT(IFERROR(INDEX($D:$D,MATCH(V5,$A:$A,0)),""),FIND(",",IFERROR(INDEX($D:$D,MATCH(V5,$A:$A,0)),""))-1),IFERROR(INDEX($D:$D,MATCH(V5,$A:$A,0)),""))))) | X5: =IF(W5="","",IF(IFERROR(INDEX($D:$D,MATCH(W5,$A:$A,0)),"")="","",TRIM(IF(ISNUMBER(FIND(",",IFERROR(INDEX($D:$D,MATCH(W5,$A:$A,0)),""))),LEFT(IFERROR(INDEX($D:$D,MATCH(W5,$A:$A,0)),""),FIND(",",IFERROR(INDEX($D:$D,MATCH(W5,$A:$A,0)),""))-1),IFERROR(INDEX($D:$D,MATCH(W5,$A:$A,0)),""))))) | Y5: =IF(X5="","",IF(IFERROR(INDEX($D:$D,MATCH(X5,$A:$A,0)),"")="","",TRIM(IF(ISNUMBER(FIND(",",IFERROR(INDEX($D:$D,MATCH(X5,$A:$A,0)),""))),LEFT(IFERROR(INDEX($D:$D,MATCH(X5,$A:$A,0)),""),FIND(",",IFERROR(INDEX($D:$D,MATCH(X5,$A:$A,0)),""))-1),IFERROR(INDEX($D:$D,MATCH(X5,$A:$A,0)),""))))) | Z5: =IF(AND(A5<>"",L5="Retire"),COUNTIF($L$5:L5,"Retire"),"") | AA5: =IF(AND(A5<>"",L5="Build"),COUNTIF($L$5:L5,"Build"),"") | AB5: =IF(AND(A5<>"",OR(M5="4+",AND(ISNUMBER(M5),M5>=2))),SUMPRODUCT(($A$5:A5<>"")*(($M$5:M5="4+")+(ISNUMBER($M$5:M5)*($M$5:M5>=2)))),"") | AC5: =IF(AND(A5<>"",OR(L5="",L5="Undecided",K5="")),SUMPRODUCT(($A$5:A5<>"")*(($L$5:L5="")+($L$5:L5="Undecided")+($K$5:K5=""))>0*1),"")
A6: T-002 | B6: HRDW requisition history table | C6: HRDW | E6: Change history for requisitions: owner changes, transfers, status changes. | F6: PDP | G6: PDP | I6: Daily | J6: Active | K6: Source tables | L6: Keep as is | M6: =IF(A6="","",IF(V6="",0,IF(W6="",1,IF(X6="",2,IF(Y6="",3,"4+"))))) -> 0 | N6: =IF(A6="","",A6&IF(V6="",""," <- "&V6&IF(W6="",""," <- "&W6&IF(X6="",""," <- "&X6&IF(Y6="",""," <- "&Y6))))&IF(ISNUMBER(FIND(",",D6))," (+ other parents)","")) -> T-002 | O6: =IF(A6="","",COUNTIF(Fields!$D:$D,A6)) -> 2 | P6: =IF(A6="","",SUMIF(Fields!$D:$D,A6,Fields!$O:$O)) -> 0 | Q6: Example. | S6: Human | T6: 2026-10-07 | V6: =IF(A6="","",IF(IFERROR(INDEX($D:$D,MATCH(A6,$A:$A,0)),"")="","",TRIM(IF(ISNUMBER(FIND(",",IFERROR(INDEX($D:$D,MATCH(A6,$A:$A,0)),""))),LEFT(IFERROR(INDEX($D:$D,MATCH(A6,$A:$A,0)),""),FIND(",",IFERROR(INDEX($D:$D,MATCH(A6,$A:$A,0)),""))-1),IFERROR(INDEX($D:$D,MATCH(A6,$A:$A,0)),""))))) | W6: =IF(V6="","",IF(IFERROR(INDEX($D:$D,MATCH(V6,$A:$A,0)),"")="","",TRIM(IF(ISNUMBER(FIND(",",IFERROR(INDEX($D:$D,MATCH(V6,$A:$A,0)),""))),LEFT(IFERROR(INDEX($D:$D,MATCH(V6,$A:$A,0)),""),FIND(",",IFERROR(INDEX($D:$D,MATCH(V6,$A:$A,0)),""))-1),IFERROR(INDEX($D:$D,MATCH(V6,$A:$A,0)),""))))) | X6: =IF(W6="","",IF(IFERROR(INDEX($D:$D,MATCH(W6,$A:$A,0)),"")="","",TRIM(IF(ISNUMBER(FIND(",",IFERROR(INDEX($D:$D,MATCH(W6,$A:$A,0)),""))),LEFT(IFERROR(INDEX($D:$D,MATCH(W6,$A:$A,0)),""),FIND(",",IFERROR(INDEX($D:$D,MATCH(W6,$A:$A,0)),""))-1),IFERROR(INDEX($D:$D,MATCH(W6,$A:$A,0)),""))))) | Y6: =IF(X6="","",IF(IFERROR(INDEX($D:$D,MATCH(X6,$A:$A,0)),"")="","",TRIM(IF(ISNUMBER(FIND(",",IFERROR(INDEX($D:$D,MATCH(X6,$A:$A,0)),""))),LEFT(IFERROR(INDEX($D:$D,MATCH(X6,$A:$A,0)),""),FIND(",",IFERROR(INDEX($D:$D,MATCH(X6,$A:$A,0)),""))-1),IFERROR(INDEX($D:$D,MATCH(X6,$A:$A,0)),""))))) | Z6: =IF(AND(A6<>"",L6="Retire"),COUNTIF($L$5:L6,"Retire"),"") | AA6: =IF(AND(A6<>"",L6="Build"),COUNTIF($L$5:L6,"Build"),"") | AB6: =IF(AND(A6<>"",OR(M6="4+",AND(ISNUMBER(M6),M6>=2))),SUMPRODUCT(($A$5:A6<>"")*(($M$5:M6="4+")+(ISNUMBER($M$5:M6)*($M$5:M6>=2)))),"") | AC6: =IF(AND(A6<>"",OR(L6="",L6="Undecided",K6="")),SUMPRODUCT(($A$5:A6<>"")*(($L$5:L6="")+($L$5:L6="Undecided")+($K$5:K6=""))>0*1),"")
A7: T-003 | B7: HRDW offer table | C7: HRDW | E7: Offers extended and their outcome. | F7: PDP | G7: PDP | I7: Daily | J7: Active | K7: Source tables | L7: Keep as is | M7: =IF(A7="","",IF(V7="",0,IF(W7="",1,IF(X7="",2,IF(Y7="",3,"4+"))))) -> 0 | N7: =IF(A7="","",A7&IF(V7="",""," <- "&V7&IF(W7="",""," <- "&W7&IF(X7="",""," <- "&X7&IF(Y7="",""," <- "&Y7))))&IF(ISNUMBER(FIND(",",D7))," (+ other parents)","")) -> T-003 | O7: =IF(A7="","",COUNTIF(Fields!$D:$D,A7)) -> 2 | P7: =IF(A7="","",SUMIF(Fields!$D:$D,A7,Fields!$O:$O)) -> 5 | Q7: Example. | S7: Human | T7: 2026-10-07 | V7: =IF(A7="","",IF(IFERROR(INDEX($D:$D,MATCH(A7,$A:$A,0)),"")="","",TRIM(IF(ISNUMBER(FIND(",",IFERROR(INDEX($D:$D,MATCH(A7,$A:$A,0)),""))),LEFT(IFERROR(INDEX($D:$D,MATCH(A7,$A:$A,0)),""),FIND(",",IFERROR(INDEX($D:$D,MATCH(A7,$A:$A,0)),""))-1),IFERROR(INDEX($D:$D,MATCH(A7,$A:$A,0)),""))))) | W7: =IF(V7="","",IF(IFERROR(INDEX($D:$D,MATCH(V7,$A:$A,0)),"")="","",TRIM(IF(ISNUMBER(FIND(",",IFERROR(INDEX($D:$D,MATCH(V7,$A:$A,0)),""))),LEFT(IFERROR(INDEX($D:$D,MATCH(V7,$A:$A,0)),""),FIND(",",IFERROR(INDEX($D:$D,MATCH(V7,$A:$A,0)),""))-1),IFERROR(INDEX($D:$D,MATCH(V7,$A:$A,0)),""))))) | X7: =IF(W7="","",IF(IFERROR(INDEX($D:$D,MATCH(W7,$A:$A,0)),"")="","",TRIM(IF(ISNUMBER(FIND(",",IFERROR(INDEX($D:$D,MATCH(W7,$A:$A,0)),""))),LEFT(IFERROR(INDEX($D:$D,MATCH(W7,$A:$A,0)),""),FIND(",",IFERROR(INDEX($D:$D,MATCH(W7,$A:$A,0)),""))-1),IFERROR(INDEX($D:$D,MATCH(W7,$A:$A,0)),""))))) | Y7: =IF(X7="","",IF(IFERROR(INDEX($D:$D,MATCH(X7,$A:$A,0)),"")="","",TRIM(IF(ISNUMBER(FIND(",",IFERROR(INDEX($D:$D,MATCH(X7,$A:$A,0)),""))),LEFT(IFERROR(INDEX($D:$D,MATCH(X7,$A:$A,0)),""),FIND(",",IFERROR(INDEX($D:$D,MATCH(X7,$A:$A,0)),""))-1),IFERROR(INDEX($D:$D,MATCH(X7,$A:$A,0)),""))))) | Z7: =IF(AND(A7<>"",L7="Retire"),COUNTIF($L$5:L7,"Retire"),"") | AA7: =IF(AND(A7<>"",L7="Build"),COUNTIF($L$5:L7,"Build"),"") | AB7: =IF(AND(A7<>"",OR(M7="4+",AND(ISNUMBER(M7),M7>=2))),SUMPRODUCT(($A$5:A7<>"")*(($M$5:M7="4+")+(ISNUMBER($M$5:M7)*($M$5:M7>=2)))),"") | AC7: =IF(AND(A7<>"",OR(L7="",L7="Undecided",K7="")),SUMPRODUCT(($A$5:A7<>"")*(($L$5:L7="")+($L$5:L7="Undecided")+($K$5:K7=""))>0*1),"")
A8: T-004 | B8: Requisition linkage table | C8: Team custom | D8: T-002 | E8: Maps a transferred requisition to its original so clocks keep running from the original approval. Nothing upstream provides this. | F8: Team Opportunity | G8: Team Opportunity | I8: Daily | J8: Active | K8: Business rules | L8: Keep as is | M8: =IF(A8="","",IF(V8="",0,IF(W8="",1,IF(X8="",2,IF(Y8="",3,"4+"))))) -> 1 | N8: =IF(A8="","",A8&IF(V8="",""," <- "&V8&IF(W8="",""," <- "&W8&IF(X8="",""," <- "&X8&IF(Y8="",""," <- "&Y8))))&IF(ISNUMBER(FIND(",",D8))," (+ other parents)","")) -> T-004 <- T-002 | O8: =IF(A8="","",COUNTIF(Fields!$D:$D,A8)) -> 1 | P8: =IF(A8="","",SUMIF(Fields!$D:$D,A8,Fields!$O:$O)) -> 2 | Q8: Example. A rule no source system knows. | R8: repo/sql/req_linkage.sql | S8: Found | T8: 2026-10-07 | V8: =IF(A8="","",IF(IFERROR(INDEX($D:$D,MATCH(A8,$A:$A,0)),"")="","",TRIM(IF(ISNUMBER(FIND(",",IFERROR(INDEX($D:$D,MATCH(A8,$A:$A,0)),""))),LEFT(IFERROR(INDEX($D:$D,MATCH(A8,$A:$A,0)),""),FIND(",",IFERROR(INDEX($D:$D,MATCH(A8,$A:$A,0)),""))-1),IFERROR(INDEX($D:$D,MATCH(A8,$A:$A,0)),""))))) -> T-002 | W8: =IF(V8="","",IF(IFERROR(INDEX($D:$D,MATCH(V8,$A:$A,0)),"")="","",TRIM(IF(ISNUMBER(FIND(",",IFERROR(INDEX($D:$D,MATCH(V8,$A:$A,0)),""))),LEFT(IFERROR(INDEX($D:$D,MATCH(V8,$A:$A,0)),""),FIND(",",IFERROR(INDEX($D:$D,MATCH(V8,$A:$A,0)),""))-1),IFERROR(INDEX($D:$D,MATCH(V8,$A:$A,0)),""))))) | X8: =IF(W8="","",IF(IFERROR(INDEX($D:$D,MATCH(W8,$A:$A,0)),"")="","",TRIM(IF(ISNUMBER(FIND(",",IFERROR(INDEX($D:$D,MATCH(W8,$A:$A,0)),""))),LEFT(IFERROR(INDEX($D:$D,MATCH(W8,$A:$A,0)),""),FIND(",",IFERROR(INDEX($D:$D,MATCH(W8,$A:$A,0)),""))-1),IFERROR(INDEX($D:$D,MATCH(W8,$A:$A,0)),""))))) | Y8: =IF(X8="","",IF(IFERROR(INDEX($D:$D,MATCH(X8,$A:$A,0)),"")="","",TRIM(IF(ISNUMBER(FIND(",",IFERROR(INDEX($D:$D,MATCH(X8,$A:$A,0)),""))),LEFT(IFERROR(INDEX($D:$D,MATCH(X8,$A:$A,0)),""),FIND(",",IFERROR(INDEX($D:$D,MATCH(X8,$A:$A,0)),""))-1),IFERROR(INDEX($D:$D,MATCH(X8,$A:$A,0)),""))))) | Z8: =IF(AND(A8<>"",L8="Retire"),COUNTIF($L$5:L8,"Retire"),"") | AA8: =IF(AND(A8<>"",L8="Build"),COUNTIF($L$5:L8,"Build"),"") | AB8: =IF(AND(A8<>"",OR(M8="4+",AND(ISNUMBER(M8),M8>=2))),SUMPRODUCT(($A$5:A8<>"")*(($M$5:M8="4+")+(ISNUMBER($M$5:M8)*($M$5:M8>=2)))),"") | AC8: =IF(AND(A8<>"",OR(L8="",L8="Undecided",K8="")),SUMPRODUCT(($A$5:A8<>"")*(($L$5:L8="")+($L$5:L8="Undecided")+($K$5:K8=""))>0*1),"")
A9: T-005 | B9: Recruiter scorecard base | C9: Team custom | D9: T-004, T-001, T-003 | E9: Built in 2023 for the recruiter view. Joins linkage, requisitions and offers and adds recruiter credit. | F9: Team Opportunity | G9: Team Opportunity | I9: Daily | J9: Active | K9: Business rules | L9: Merge into certified table | M9: =IF(A9="","",IF(V9="",0,IF(W9="",1,IF(X9="",2,IF(Y9="",3,"4+"))))) -> 2 | N9: =IF(A9="","",A9&IF(V9="",""," <- "&V9&IF(W9="",""," <- "&W9&IF(X9="",""," <- "&X9&IF(Y9="",""," <- "&Y9))))&IF(ISNUMBER(FIND(",",D9))," (+ other parents)","")) -> T-005 <- T-004 <- T-002 (+ other parents) | O9: =IF(A9="","",COUNTIF(Fields!$D:$D,A9)) -> 1 | P9: =IF(A9="","",SUMIF(Fields!$D:$D,A9,Fields!$O:$O)) -> 2 | Q9: Example. Depth 2: a layer on a layer. Candidate to fold into the certified table. | R9: repo/sql/recruiter_base.sql | S9: Found | T9: 2026-10-07 | V9: =IF(A9="","",IF(IFERROR(INDEX($D:$D,MATCH(A9,$A:$A,0)),"")="","",TRIM(IF(ISNUMBER(FIND(",",IFERROR(INDEX($D:$D,MATCH(A9,$A:$A,0)),""))),LEFT(IFERROR(INDEX($D:$D,MATCH(A9,$A:$A,0)),""),FIND(",",IFERROR(INDEX($D:$D,MATCH(A9,$A:$A,0)),""))-1),IFERROR(INDEX($D:$D,MATCH(A9,$A:$A,0)),""))))) -> T-004 | W9: =IF(V9="","",IF(IFERROR(INDEX($D:$D,MATCH(V9,$A:$A,0)),"")="","",TRIM(IF(ISNUMBER(FIND(",",IFERROR(INDEX($D:$D,MATCH(V9,$A:$A,0)),""))),LEFT(IFERROR(INDEX($D:$D,MATCH(V9,$A:$A,0)),""),FIND(",",IFERROR(INDEX($D:$D,MATCH(V9,$A:$A,0)),""))-1),IFERROR(INDEX($D:$D,MATCH(V9,$A:$A,0)),""))))) -> T-002 | X9: =IF(W9="","",IF(IFERROR(INDEX($D:$D,MATCH(W9,$A:$A,0)),"")="","",TRIM(IF(ISNUMBER(FIND(",",IFERROR(INDEX($D:$D,MATCH(W9,$A:$A,0)),""))),LEFT(IFERROR(INDEX($D:$D,MATCH(W9,$A:$A,0)),""),FIND(",",IFERROR(INDEX($D:$D,MATCH(W9,$A:$A,0)),""))-1),IFERROR(INDEX($D:$D,MATCH(W9,$A:$A,0)),""))))) | Y9: =IF(X9="","",IF(IFERROR(INDEX($D:$D,MATCH(X9,$A:$A,0)),"")="","",TRIM(IF(ISNUMBER(FIND(",",IFERROR(INDEX($D:$D,MATCH(X9,$A:$A,0)),""))),LEFT(IFERROR(INDEX($D:$D,MATCH(X9,$A:$A,0)),""),FIND(",",IFERROR(INDEX($D:$D,MATCH(X9,$A:$A,0)),""))-1),IFERROR(INDEX($D:$D,MATCH(X9,$A:$A,0)),""))))) | Z9: =IF(AND(A9<>"",L9="Retire"),COUNTIF($L$5:L9,"Retire"),"") | AA9: =IF(AND(A9<>"",L9="Build"),COUNTIF($L$5:L9,"Build"),"") | AB9: =IF(AND(A9<>"",OR(M9="4+",AND(ISNUMBER(M9),M9>=2))),SUMPRODUCT(($A$5:A9<>"")*(($M$5:M9="4+")+(ISNUMBER($M$5:M9)*($M$5:M9>=2)))),"") -> 1 | AC9: =IF(AND(A9<>"",OR(L9="",L9="Undecided",K9="")),SUMPRODUCT(($A$5:A9<>"")*(($L$5:L9="")+($L$5:L9="Undecided")+($K$5:K9=""))>0*1),"")
A10: T-006 | B10: Recruiter view extract | C10: Team custom | D10: T-005 | E10: Narrow copy of the recruiter base shaped for the Tableau extract. | F10: Team Opportunity | G10: Team Opportunity | I10: Daily | J10: Active | K10: Reporting | L10: Retire | M10: =IF(A10="","",IF(V10="",0,IF(W10="",1,IF(X10="",2,IF(Y10="",3,"4+"))))) -> 3 | N10: =IF(A10="","",A10&IF(V10="",""," <- "&V10&IF(W10="",""," <- "&W10&IF(X10="",""," <- "&X10&IF(Y10="",""," <- "&Y10))))&IF(ISNUMBER(FIND(",",D10))," (+ other parents)","")) -> T-006 <- T-005 <- T-004 <- T-002 | O10: =IF(A10="","",COUNTIF(Fields!$D:$D,A10)) -> 0 | P10: =IF(A10="","",SUMIF(Fields!$D:$D,A10,Fields!$O:$O)) -> 0 | Q10: Example. Depth 3. Exists only to feed one dashboard; goes away when the dashboard reads the certified table. | R10: repo/sql/recruiter_extract.sql | S10: Found | T10: 2026-10-07 | V10: =IF(A10="","",IF(IFERROR(INDEX($D:$D,MATCH(A10,$A:$A,0)),"")="","",TRIM(IF(ISNUMBER(FIND(",",IFERROR(INDEX($D:$D,MATCH(A10,$A:$A,0)),""))),LEFT(IFERROR(INDEX($D:$D,MATCH(A10,$A:$A,0)),""),FIND(",",IFERROR(INDEX($D:$D,MATCH(A10,$A:$A,0)),""))-1),IFERROR(INDEX($D:$D,MATCH(A10,$A:$A,0)),""))))) -> T-005 | W10: =IF(V10="","",IF(IFERROR(INDEX($D:$D,MATCH(V10,$A:$A,0)),"")="","",TRIM(IF(ISNUMBER(FIND(",",IFERROR(INDEX($D:$D,MATCH(V10,$A:$A,0)),""))),LEFT(IFERROR(INDEX($D:$D,MATCH(V10,$A:$A,0)),""),FIND(",",IFERROR(INDEX($D:$D,MATCH(V10,$A:$A,0)),""))-1),IFERROR(INDEX($D:$D,MATCH(V10,$A:$A,0)),""))))) -> T-004 | X10: =IF(W10="","",IF(IFERROR(INDEX($D:$D,MATCH(W10,$A:$A,0)),"")="","",TRIM(IF(ISNUMBER(FIND(",",IFERROR(INDEX($D:$D,MATCH(W10,$A:$A,0)),""))),LEFT(IFERROR(INDEX($D:$D,MATCH(W10,$A:$A,0)),""),FIND(",",IFERROR(INDEX($D:$D,MATCH(W10,$A:$A,0)),""))-1),IFERROR(INDEX($D:$D,MATCH(W10,$A:$A,0)),""))))) -> T-002 | Y10: =IF(X10="","",IF(IFERROR(INDEX($D:$D,MATCH(X10,$A:$A,0)),"")="","",TRIM(IF(ISNUMBER(FIND(",",IFERROR(INDEX($D:$D,MATCH(X10,$A:$A,0)),""))),LEFT(IFERROR(INDEX($D:$D,MATCH(X10,$A:$A,0)),""),FIND(",",IFERROR(INDEX($D:$D,MATCH(X10,$A:$A,0)),""))-1),IFERROR(INDEX($D:$D,MATCH(X10,$A:$A,0)),""))))) | Z10: =IF(AND(A10<>"",L10="Retire"),COUNTIF($L$5:L10,"Retire"),"") -> 1 | AA10: =IF(AND(A10<>"",L10="Build"),COUNTIF($L$5:L10,"Build"),"") | AB10: =IF(AND(A10<>"",OR(M10="4+",AND(ISNUMBER(M10),M10>=2))),SUMPRODUCT(($A$5:A10<>"")*(($M$5:M10="4+")+(ISNUMBER($M$5:M10)*($M$5:M10>=2)))),"") -> 2 | AC10: =IF(AND(A10<>"",OR(L10="",L10="Undecided",K10="")),SUMPRODUCT(($A$5:A10<>"")*(($L$5:L10="")+($L$5:L10="Undecided")+($K$5:K10=""))>0*1),"")
A11: T-007 | B11: Certified application table | C11: Team custom | D11: T-001, T-002, T-003, T-004 | E11: One row per application with agreed attribution and exclusion flags applied, so every product reads the same rules. | F11: Team Opportunity | G11: Team Opportunity | I11: Daily | J11: Proposed | K11: Certified tables | L11: Build | M11: =IF(A11="","",IF(V11="",0,IF(W11="",1,IF(X11="",2,IF(Y11="",3,"4+"))))) -> 1 | N11: =IF(A11="","",A11&IF(V11="",""," <- "&V11&IF(W11="",""," <- "&W11&IF(X11="",""," <- "&X11&IF(Y11="",""," <- "&Y11))))&IF(ISNUMBER(FIND(",",D11))," (+ other parents)","")) -> T-007 <- T-001 (+ other parents) | O11: =IF(A11="","",COUNTIF(Fields!$D:$D,A11)) -> 0 | P11: =IF(A11="","",SUMIF(Fields!$D:$D,A11,Fields!$O:$O)) -> 0 | Q11: Example. Proposed; appears because dispositions above call for it. | S11: Human | T11: 2026-10-07 | V11: =IF(A11="","",IF(IFERROR(INDEX($D:$D,MATCH(A11,$A:$A,0)),"")="","",TRIM(IF(ISNUMBER(FIND(",",IFERROR(INDEX($D:$D,MATCH(A11,$A:$A,0)),""))),LEFT(IFERROR(INDEX($D:$D,MATCH(A11,$A:$A,0)),""),FIND(",",IFERROR(INDEX($D:$D,MATCH(A11,$A:$A,0)),""))-1),IFERROR(INDEX($D:$D,MATCH(A11,$A:$A,0)),""))))) -> T-001 | W11: =IF(V11="","",IF(IFERROR(INDEX($D:$D,MATCH(V11,$A:$A,0)),"")="","",TRIM(IF(ISNUMBER(FIND(",",IFERROR(INDEX($D:$D,MATCH(V11,$A:$A,0)),""))),LEFT(IFERROR(INDEX($D:$D,MATCH(V11,$A:$A,0)),""),FIND(",",IFERROR(INDEX($D:$D,MATCH(V11,$A:$A,0)),""))-1),IFERROR(INDEX($D:$D,MATCH(V11,$A:$A,0)),""))))) | X11: =IF(W11="","",IF(IFERROR(INDEX($D:$D,MATCH(W11,$A:$A,0)),"")="","",TRIM(IF(ISNUMBER(FIND(",",IFERROR(INDEX($D:$D,MATCH(W11,$A:$A,0)),""))),LEFT(IFERROR(INDEX($D:$D,MATCH(W11,$A:$A,0)),""),FIND(",",IFERROR(INDEX($D:$D,MATCH(W11,$A:$A,0)),""))-1),IFERROR(INDEX($D:$D,MATCH(W11,$A:$A,0)),""))))) | Y11: =IF(X11="","",IF(IFERROR(INDEX($D:$D,MATCH(X11,$A:$A,0)),"")="","",TRIM(IF(ISNUMBER(FIND(",",IFERROR(INDEX($D:$D,MATCH(X11,$A:$A,0)),""))),LEFT(IFERROR(INDEX($D:$D,MATCH(X11,$A:$A,0)),""),FIND(",",IFERROR(INDEX($D:$D,MATCH(X11,$A:$A,0)),""))-1),IFERROR(INDEX($D:$D,MATCH(X11,$A:$A,0)),""))))) | Z11: =IF(AND(A11<>"",L11="Retire"),COUNTIF($L$5:L11,"Retire"),"") | AA11: =IF(AND(A11<>"",L11="Build"),COUNTIF($L$5:L11,"Build"),"") -> 1 | AB11: =IF(AND(A11<>"",OR(M11="4+",AND(ISNUMBER(M11),M11>=2))),SUMPRODUCT(($A$5:A11<>"")*(($M$5:M11="4+")+(ISNUMBER($M$5:M11)*($M$5:M11>=2)))),"") | AC11: =IF(AND(A11<>"",OR(L11="",L11="Undecided",K11="")),SUMPRODUCT(($A$5:A11<>"")*(($L$5:L11="")+($L$5:L11="Undecided")+($K$5:K11=""))>0*1),"")
M12: =IF(A12="","",IF(V12="",0,IF(W12="",1,IF(X12="",2,IF(Y12="",3,"4+"))))) | N12: =IF(A12="","",A12&IF(V12="",""," <- "&V12&IF(W12="",""," <- "&W12&IF(X12="",""," <- "&X12&IF(Y12="",""," <- "&Y12))))&IF(ISNUMBER(FIND(",",D12))," (+ other parents)","")) | O12: =IF(A12="","",COUNTIF(Fields!$D:$D,A12)) | P12: =IF(A12="","",SUMIF(Fields!$D:$D,A12,Fields!$O:$O)) | V12: =IF(A12="","",IF(IFERROR(INDEX($D:$D,MATCH(A12,$A:$A,0)),"")="","",TRIM(IF(ISNUMBER(FIND(",",IFERROR(INDEX($D:$D,MATCH(A12,$A:$A,0)),""))),LEFT(IFERROR(INDEX($D:$D,MATCH(A12,$A:$A,0)),""),FIND(",",IFERROR(INDEX($D:$D,MATCH(A12,$A:$A,0)),""))-1),IFERROR(INDEX($D:$D,MATCH(A12,$A:$A,0)),""))))) | W12: =IF(V12="","",IF(IFERROR(INDEX($D:$D,MATCH(V12,$A:$A,0)),"")="","",TRIM(IF(ISNUMBER(FIND(",",IFERROR(INDEX($D:$D,MATCH(V12,$A:$A,0)),""))),LEFT(IFERROR(INDEX($D:$D,MATCH(V12,$A:$A,0)),""),FIND(",",IFERROR(INDEX($D:$D,MATCH(V12,$A:$A,0)),""))-1),IFERROR(INDEX($D:$D,MATCH(V12,$A:$A,0)),""))))) | X12: =IF(W12="","",IF(IFERROR(INDEX($D:$D,MATCH(W12,$A:$A,0)),"")="","",TRIM(IF(ISNUMBER(FIND(",",IFERROR(INDEX($D:$D,MATCH(W12,$A:$A,0)),""))),LEFT(IFERROR(INDEX($D:$D,MATCH(W12,$A:$A,0)),""),FIND(",",IFERROR(INDEX($D:$D,MATCH(W12,$A:$A,0)),""))-1),IFERROR(INDEX($D:$D,MATCH(W12,$A:$A,0)),""))))) | Y12: =IF(X12="","",IF(IFERROR(INDEX($D:$D,MATCH(X12,$A:$A,0)),"")="","",TRIM(IF(ISNUMBER(FIND(",",IFERROR(INDEX($D:$D,MATCH(X12,$A:$A,0)),""))),LEFT(IFERROR(INDEX($D:$D,MATCH(X12,$A:$A,0)),""),FIND(",",IFERROR(INDEX($D:$D,MATCH(X12,$A:$A,0)),""))-1),IFERROR(INDEX($D:$D,MATCH(X12,$A:$A,0)),""))))) | Z12: =IF(AND(A12<>"",L12="Retire"),COUNTIF($L$5:L12,"Retire"),"") | AA12: =IF(AND(A12<>"",L12="Build"),COUNTIF($L$5:L12,"Build"),"") | AB12: =IF(AND(A12<>"",OR(M12="4+",AND(ISNUMBER(M12),M12>=2))),SUMPRODUCT(($A$5:A12<>"")*(($M$5:M12="4+")+(ISNUMBER($M$5:M12)*($M$5:M12>=2)))),"") | AC12: =IF(AND(A12<>"",OR(L12="",L12="Undecided",K12="")),SUMPRODUCT(($A$5:A12<>"")*(($L$5:L12="")+($L$5:L12="Undecided")+($K$5:K12=""))>0*1),"")
